Workbook
Name \0: #REF!
Name \A: #REF!
Name \B: #REF!
Name \C: #REF!
Name \D: #REF!
Name \F: #REF!
Name \G: #REF!
Name \H: #REF!
Name \I: #REF!
Name \J: #REF!
Name \K: #REF!
Name \L: #REF!
Name \M: #REF!
Name \N: #REF!
Name \new: #REF!
Name \P: #REF!
Name \Q: #REF!
Name \U: #REF!
Name \V: #REF!
Name \Z: #REF!
Name ______________________tax1: #REF!
Name ______________________tax2: #REF!
Name ______________________tax3: #REF!
Name ______________________tax4: #REF!
Name _____________________tax1: #REF!
Name _____________________tax2: #REF!
Name _____________________tax3: #REF!
Name _____________________tax4: #REF!
Name ____________________tax1: #REF!
Name ____________________tax2: #REF!
Name ____________________tax3: #REF!
Name ____________________tax4: #REF!
Name ___________________tax1: #REF!
Name ___________________tax2: #REF!
Name ___________________tax3: #REF!
Name ___________________tax4: #REF!
Name __________________tax1: #REF!
Name __________________tax2: #REF!
Name __________________tax3: #REF!
Name __________________tax4: #REF!
Name _________________tax1: #REF!
Name _________________tax2: #REF!
Name _________________tax3: #REF!
Name _________________tax4: #REF!
Name ________________tax1: #REF!
Name ________________tax2: #REF!
Name ________________tax3: #REF!
Name ________________tax4: #REF!
Name _______________tax1: #REF!
Name _______________tax2: #REF!
Name _______________tax3: #REF!
Name _______________tax4: #REF!
Name ______________tax1: #REF!
Name ______________tax2: #REF!
Name ______________tax3: #REF!
Name ______________tax4: #REF!
Name _____________tax1: #REF!
Name _____________tax2: #REF!
Name _____________tax3: #REF!
Name _____________tax4: #REF!

Sheet STOC Accounting Diligence Datab
A1: =Project&" - "&City&", "&State -> OPEN - OPEN, OPEN
A2: =MID(CELL("filename",A1),FIND("]",CELL("filename",A1))+1,255) -> STOC Accounting Diligence Datab
B4: Input Tab
A6: Tab delineation
B7: Tab is completed and ready to be sent to the Client
B8: Tab has been completed by junior staff and is ready for review
B9: Tab has been started, but awaiting information from Client
B10: Tab has not been started
B11: Source file
A13: Project:
A14: Project Name | B14: OPEN
A15: Location of Practice (City) | B15: OPEN
A16: Location of Practice (State) | B16: OPEN
A18: Financial / reporting period:
A19: External Financial Statement | B19: Tax Return
A21: Calendar Year / Fiscal Year | B21: Calendar
A22: Stub Period | B22: 45565 | D22: =IF($B$21="Fiscal", "Hardkey (i) stub period date and (ii) second full year date","")
A23: Financial Reporting Period 2 | B23: =IF($B$21="Calendar",EOMONTH(B22,-MONTH(B22)),0) -> 45291 | D23: =IF($B$21="Fiscal", "Hardkey (i) stub period date and (ii) second full year date","")
A24: Financial Reporting Period 1 | B24: 44926 | D24: =IF($B$21="Fiscal", "Hardkey (i) stub period date and (ii) second full year date","")
A26: Tab checks:
A27: QE Summary | B27: =IFERROR(ROUND(SUM('QE Summary'!$D$50:$G$50),0),"")
A28: Recast Reported | B28: =IFERROR(ROUND(SUM('Recast Reported'!$C$46:$AN$46),0),"") -> 0
A29: Recast Mgmt. Adjusted | B29: =IFERROR(ROUND(SUM('Recast Mgmt. Adjusted'!$C$46:$AN$46),0),"") -> 0
A30: Other Recast | B30: =IFERROR(ROUND(SUM(#REF!)+SUM(#REF!),0),"")
A31: Lead Profit and Loss | B31: =IFERROR(ROUND(SUM('Lead PL'!$B$25:$H$25),0),"") -> 0
A32: Monthly Profit and Loss | B32: =IFERROR(ROUND(SUM(PL!$L$84:$AM$84),0),"") -> 0
A66: States
A67: AL
A68: AK
A69: AZ
A70: AR
A71: CA
A72: CO
A73: CT
A74: DE
A75: FL
A76: GA
A77: HI
... A116: WY

Sheet Cover >>>
B12: Quality of Earnings Analysis [DRAFT]
B14: =Project&" - "&City&", "&State -> OPEN - OPEN, OPEN
B15: =TODAY() -> 45819
A31: CONFIDENTIAL

Sheet QE Summary
A1: =Project&" - "&City&", "&State -> OPEN - OPEN, OPEN
A2: =MID(CELL("filename",A1),FIND("]",CELL("filename",A1))+1,255) -> QE Summary
A4: QE Summary
D5: QE Summary
D6: =First_Reporting_Year -> 44926 | E6: =Second_Reporting_Year -> 45291 | F6: =Stub_Period -> 45565 | I6: FY22 to FY23 | K6: FY23 to TTM24
C7: Revenue | I7: =+E7-D7 -> 0 | K7: =+F7-E7 -> 0
C8: YoY Change | D8: n/a | E8: =+((E7-D$7)/D$7)*100 -> #DIV/0! | F8: =+((F7-E$7)/E$7)*100 -> #DIV/0!
C10: Dental supplies | I10: =+E10-D10 -> 0 | K10: =+F10-E10 -> 0
C11: Ortho supplies | I11: =+E11-D11 -> 0 | K11: =+F11-E11 -> 0
C12: Lab fees | I12: =+E12-D12 -> 0 | K12: =+F12-E12 -> 0
C13: Gross Profit | D13: =D7-SUM(D10:D12) -> 0 | E13: =E7-SUM(E10:E12) -> 0 | F13: =F7-SUM(F10:F12) -> 0 | I13: =I7-SUM(I10:I12) -> 0 | J13: =J7-SUM(J10:J12) -> 0 | K13: =K7-SUM(K10:K12) -> 0 | L13: =L7-SUM(L10:L12) -> 0
C14: Gross Margin | D14: =+IFERROR(D13/D$7*100,0) -> 0 | E14: =+IFERROR(E13/E$7*100,0) -> 0 | F14: =+IFERROR(F13/F$7*100,0) -> 0
C16: Doctor wages | I16: =+E16-D16 -> 0 | K16: =+F16-E16 -> 0
C17: Clinic wages | I17: =+E17-D17 -> 0 | K17: =+F17-E17 -> 0
C18: Admin wages | I18: =+E18-D18 -> 0 | K18: =+F18-E18 -> 0
C19: Gross wages | I19: =+E19-D19 -> 0 | K19: =+F19-E19 -> 0
C20: Payroll taxes | I20: =+E20-D20 -> 0 | K20: =+F20-E20 -> 0
C21: Insurance | I21: =+E21-D21 -> 0 | K21: =+F21-E21 -> 0
C22: Employee 401(k) | I22: =+E22-D22 -> 0 | K22: =+F22-E22 -> 0
C23: Salary, payroll taxes, and benefits, total | D23: =SUM(D19:D22) -> 0 | E23: =SUM(E19:E22) -> 0 | F23: =SUM(F19:F22) -> 0 | I23: =+E23-D23 -> 0 | K23: =+F23-E23 -> 0
C24: Rent - real property | I24: =+E24-D24 -> 0 | K24: =+F24-E24 -> 0
C25: Property tax expense | I25: =+E25-D25 -> 0 | K25: =+F25-E25 -> 0
C26: Repairs and maintenance | I26: =+E26-D26 -> 0 | K26: =+F26-E26 -> 0
C27: Utilities expense | I27: =+E27-D27 -> 0 | K27: =+F27-E27 -> 0
C28: Rent and building expenses, total | D28: =SUM(D24:D27) -> 0 | E28: =SUM(E24:E27) -> 0 | F28: =SUM(F24:F27) -> 0 | I28: =+E28-D28 -> 0 | K28: =+F28-E28 -> 0
C29: Advertising | I29: =+E29-D29 -> 0 | K29: =+F29-E29 -> 0
C30: Other | I30: =+E30-D30 -> 0 | K30: =+F30-E30 -> 0
C31: Adjusted EBITDA | D31: =D13-SUM(D23,D28:D30) -> 0 | E31: =E13-SUM(E23,E28:E30) -> 0 | F31: =F13-SUM(F23,F28:F30) -> 0 | I31: =I13-SUM(I23,I28:I30) -> 0 | J31: =J13-SUM(J23,J28:J30) -> 0 | K31: =K13-SUM(K23,K28:K30) -> 0 | L31: =L13-SUM(L23,L28:L30) -> 0
C32: Adjusted EBITDA % | D32: =+IFERROR(D31/D$7*100,0) -> 0 | E32: =+IFERROR(E31/E$7*100,0) -> 0 | F32: =+IFERROR(F31/F$7*100,0) -> 0
C34: =C10 -> Dental supplies | D34: =+IFERROR(D10/D$7*100,0) -> 0 | E34: =+IFERROR(E10/E$7*100,0) -> 0 | F34: =+IFERROR(F10/F$7*100,0) -> 0
C35: =C11 -> Ortho supplies | D35: =+IFERROR(D11/D$7*100,0) -> 0 | E35: =+IFERROR(E11/E$7*100,0) -> 0 | F35: =+IFERROR(F11/F$7*100,0) -> 0
C36: =C12 -> Lab fees | D36: =+IFERROR(D12/D$7*100,0) -> 0 | E36: =+IFERROR(E12/E$7*100,0) -> 0 | F36: =+IFERROR(F12/F$7*100,0) -> 0
C37: =C16 -> Doctor wages | D37: =+IFERROR(D16/D$7*100,0) -> 0 | E37: =+IFERROR(E16/E$7*100,0) -> 0 | F37: =+IFERROR(F16/F$7*100,0) -> 0
C38: =C17 -> Clinic wages | D38: =+IFERROR(D17/D$7*100,0) -> 0 | E38: =+IFERROR(E17/E$7*100,0) -> 0 | F38: =+IFERROR(F17/F$7*100,0) -> 0
C39: =C18 -> Admin wages | D39: =+IFERROR(D18/D$7*100,0) -> 0 | E39: =+IFERROR(E18/E$7*100,0) -> 0 | F39: =+IFERROR(F18/F$7*100,0) -> 0
C40: =C20 -> Payroll taxes | D40: =+IFERROR(D20/D$7*100,0) -> 0 | E40: =+IFERROR(E20/E$7*100,0) -> 0 | F40: =+IFERROR(F20/F$7*100,0) -> 0
C41: =C21 -> Insurance | D41: =+IFERROR(D21/D$7*100,0) -> 0 | E41: =+IFERROR(E21/E$7*100,0) -> 0 | F41: =+IFERROR(F21/F$7*100,0) -> 0
C42: =C22 -> Employee 401(k) | D42: =+IFERROR(D22/D$7*100,0) -> 0 | E42: =+IFERROR(E22/E$7*100,0) -> 0 | F42: =+IFERROR(F22/F$7*100,0) -> 0
C43: =C24 -> Rent - real property | D43: =+IFERROR(D24/D$7*100,0) -> 0 | E43: =+IFERROR(E24/E$7*100,0) -> 0 | F43: =+IFERROR(F24/F$7*100,0) -> 0
C44: =C25 -> Property tax expense | D44: =+IFERROR(D25/D$7*100,0) -> 0 | E44: =+IFERROR(E25/E$7*100,0) -> 0 | F44: =+IFERROR(F25/F$7*100,0) -> 0
...

Sheet QE & Support >>>
A10: =RIGHT(CELL("filename",A1),LEN(CELL("filename",A1))-FIND("]",CELL("filename",A1))) -> QE & Support >>>

Sheet Lead QE
B1: =Project&" - "&City&", "&State -> OPEN - OPEN, OPEN
B2: =MID(CELL("filename",B1),FIND("]",CELL("filename",B1))+1,255) -> Lead QE
B4: Quality of Earnings Table
A5: LOI Mapping | B5: In $000's | C5: Ref | D5: =First_Reporting_Year -> 44926 | E5: =Second_Reporting_Year -> 45291 | F5: =Stub_Period -> 45565 | G5: 45199 | H5: 45565 | J5: =EOMONTH(D5,-11) -> 44592 | K5: =EOMONTH(J5,1) -> 44620 | L5: =EOMONTH(K5,1) -> 44651 | M5: =EOMONTH(L5,1) -> 44681 | N5: =EOMONTH(M5,1) -> 44712 | O5: =EOMONTH(N5,1) -> 44742 | P5: =EOMONTH(O5,1) -> 44773 | Q5: =EOMONTH(P5,1) -> 44804 | R5: =EOMONTH(Q5,1) -> 44834 | ... AP5: =EOMONTH(AO5,1) -> 45565
B6: Reported revenue | D6: =SUMIFS($J6:$AP6,$J$5:$AP$5,">"&EOMONTH(D$5,-12),$J$5:$AP$5,"<="&D$5) -> 0 | E6: =SUMIFS($J6:$AP6,$J$5:$AP$5,">"&EOMONTH(E$5,-12),$J$5:$AP$5,"<="&E$5) -> 0 | F6: =SUMIFS($J6:$AP6,$J$5:$AP$5,">"&EOMONTH(F$5,-12),$J$5:$AP$5,"<="&F$5) -> 0 | G6: =SUMIFS($J6:$AS6,$J$5:$AS$5,">"&EOMONTH(G$5,-9),$J$5:$AS$5,"<="&G$5) -> 0 | H6: =SUMIFS($J6:$AS6,$J$5:$AS$5,">"&EOMONTH(H$5,-9),$J$5:$AS$5,"<="&H$5) -> 0 | J6: =PL!L15 -> 0 | K6: =PL!M15 -> 0 | L6: =PL!N15 -> 0 | M6: =PL!O15 -> 0 | N6: =PL!P15 -> 0 | O6: =PL!Q15 -> 0 | P6: =PL!R15 -> 0 | Q6: =PL!S15 -> 0 | ... AK6: =PL!AM15 -> 0 | AL6: =PL!AS15 -> 0 | AM6: =PL!AT15 -> 0 | AN6: =PL!AU15 -> 0 | AO6: =PL!AV15 -> 0 | AP6: =PL!AW15 -> 0
B8: Net income | D8: =SUMIFS($J8:$AP8,$J$5:$AP$5,">"&EOMONTH(D$5,-12),$J$5:$AP$5,"<="&D$5) -> 0 | E8: =SUMIFS($J8:$AP8,$J$5:$AP$5,">"&EOMONTH(E$5,-12),$J$5:$AP$5,"<="&E$5) -> 0 | F8: =SUMIFS($J8:$AP8,$J$5:$AP$5,">"&EOMONTH(F$5,-12),$J$5:$AP$5,"<="&F$5) -> 0 | G8: =SUMIFS($J8:$AS8,$J$5:$AS$5,">"&EOMONTH(G$5,-9),$J$5:$AS$5,"<="&G$5) -> 0 | H8: =SUMIFS($J8:$AS8,$J$5:$AS$5,">"&EOMONTH(H$5,-9),$J$5:$AS$5,"<="&H$5) -> 0 | J8: =PL!L73 -> 0 | K8: =PL!M73 -> 0 | L8: =PL!N73 -> 0 | M8: =PL!O73 -> 0 | N8: =PL!P73 -> 0 | O8: =PL!Q73 -> 0 | P8: =PL!R73 -> 0 | Q8: =PL!S73 -> 0 | ... AK8: =PL!AM73 -> 0 | AL8: =PL!AS73 -> 0 | AM8: =PL!AT73 -> 0 | AN8: =PL!AU73 -> 0 | AO8: =PL!AV73 -> 0 | AP8: =PL!AW73 -> 0
B9: Depreciation and amortization | D9: =SUMIFS($J9:$AP9,$J$5:$AP$5,">"&EOMONTH(D$5,-12),$J$5:$AP$5,"<="&D$5) -> 0 | E9: =SUMIFS($J9:$AP9,$J$5:$AP$5,">"&EOMONTH(E$5,-12),$J$5:$AP$5,"<="&E$5) -> 0 | F9: =SUMIFS($J9:$AP9,$J$5:$AP$5,">"&EOMONTH(F$5,-12),$J$5:$AP$5,"<="&F$5) -> 0 | G9: =SUMIFS($J9:$AS9,$J$5:$AS$5,">"&EOMONTH(G$5,-9),$J$5:$AS$5,"<="&G$5) -> 0 | H9: =SUMIFS($J9:$AS9,$J$5:$AS$5,">"&EOMONTH(H$5,-9),$J$5:$AS$5,"<="&H$5) -> 0 | J9: =PL!L75 -> 0 | K9: =PL!M75 -> 0 | L9: =PL!N75 -> 0 | M9: =PL!O75 -> 0 | N9: =PL!P75 -> 0 | O9: =PL!Q75 -> 0 | P9: =PL!R75 -> 0 | Q9: =PL!S75 -> 0 | ... AK9: =PL!AM75 -> 0 | AL9: =PL!AS75 -> 0 | AM9: =PL!AT75 -> 0 | AN9: =PL!AU75 -> 0 | AO9: =PL!AV75 -> 0 | AP9: =PL!AW75 -> 0
B10: Interest expense | D10: =SUMIFS($J10:$AP10,$J$5:$AP$5,">"&EOMONTH(D$5,-12),$J$5:$AP$5,"<="&D$5) -> 0 | E10: =SUMIFS($J10:$AP10,$J$5:$AP$5,">"&EOMONTH(E$5,-12),$J$5:$AP$5,"<="&E$5) -> 0 | F10: =SUMIFS($J10:$AP10,$J$5:$AP$5,">"&EOMONTH(F$5,-12),$J$5:$AP$5,"<="&F$5) -> 0 | G10: =SUMIFS($J10:$AS10,$J$5:$AS$5,">"&EOMONTH(G$5,-9),$J$5:$AS$5,"<="&G$5) -> 0 | H10: =SUMIFS($J10:$AS10,$J$5:$AS$5,">"&EOMONTH(H$5,-9),$J$5:$AS$5,"<="&H$5) -> 0 | J10: =PL!L76 -> 0 | K10: =PL!M76 -> 0 | L10: =PL!N76 -> 0 | M10: =PL!O76 -> 0 | N10: =PL!P76 -> 0 | O10: =PL!Q76 -> 0 | P10: =PL!R76 -> 0 | Q10: =PL!S76 -> 0 | ... AK10: =PL!AM76 -> 0 | AL10: =PL!AS76 -> 0 | AM10: =PL!AT76 -> 0 | AN10: =PL!AU76 -> 0 | AO10: =PL!AV76 -> 0 | AP10: =PL!AW76 -> 0
B11: Income tax | D11: =SUMIFS($J11:$AP11,$J$5:$AP$5,">"&EOMONTH(D$5,-12),$J$5:$AP$5,"<="&D$5) -> 0 | E11: =SUMIFS($J11:$AP11,$J$5:$AP$5,">"&EOMONTH(E$5,-12),$J$5:$AP$5,"<="&E$5) -> 0 | F11: =SUMIFS($J11:$AP11,$J$5:$AP$5,">"&EOMONTH(F$5,-12),$J$5:$AP$5,"<="&F$5) -> 0 | G11: =SUMIFS($J11:$AS11,$J$5:$AS$5,">"&EOMONTH(G$5,-9),$J$5:$AS$5,"<="&G$5) -> 0 | H11: =SUMIFS($J11:$AS11,$J$5:$AS$5,">"&EOMONTH(H$5,-9),$J$5:$AS$5,"<="&H$5) -> 0 | J11: =PL!L77 -> 0 | K11: =PL!M77 -> 0 | L11: =PL!N77 -> 0 | M11: =PL!O77 -> 0 | N11: =PL!P77 -> 0 | O11: =PL!Q77 -> 0 | P11: =PL!R77 -> 0 | Q11: =PL!S77 -> 0 | ... AK11: =PL!AM77 -> 0 | AL11: =PL!AS77 -> 0 | AM11: =PL!AT77 -> 0 | AN11: =PL!AU77 -> 0 | AO11: =PL!AV77 -> 0 | AP11: =PL!AW77 -> 0
B12: Reported EBITDA | D12: =SUM(D8:D11) -> 0 | E12: =SUM(E8:E11) -> 0 | F12: =SUM(F8:F11) -> 0 | G12: =SUMIFS($J12:$AS12,$J$5:$AS$5,">"&EOMONTH(G$5,-9),$J$5:$AS$5,"<="&G$5) -> 0 | H12: =SUMIFS($J12:$AS12,$J$5:$AS$5,">"&EOMONTH(H$5,-9),$J$5:$AS$5,"<="&H$5) -> 0 | J12: =SUM(J8:J11) -> 0 | K12: =SUM(K8:K11) -> 0 | L12: =SUM(L8:L11) -> 0 | M12: =SUM(M8:M11) -> 0 | N12: =SUM(N8:N11) -> 0 | O12: =SUM(O8:O11) -> 0 | P12: =SUM(P8:P11) -> 0 | Q12: =SUM(Q8:Q11) -> 0 | ... AP12: =SUM(AP8:AP11) -> 0
B13: % margin | D13: =(D12/D6)*100 -> #DIV/0! | E13: =(E12/E6)*100 -> #DIV/0! | F13: =(F12/F6)*100 -> #DIV/0! | G13: =(G12/G6)*100 -> #DIV/0! | H13: =(H12/H6)*100 -> #DIV/0! | J13: =(J12/J6)*100 -> #DIV/0! | K13: =(K12/K6)*100 -> #DIV/0! | L13: =(L12/L6)*100 -> #DIV/0! | M13: =(M12/M6)*100 -> #DIV/0! | N13: =(N12/N6)*100 -> #DIV/0! | O13: =(O12/O6)*100 -> #DIV/0! | P13: =(P12/P6)*100 -> #DIV/0! | Q13: =(Q12/Q6)*100 -> #DIV/0! | ... AP13: =(AP12/AP6)*100 -> #DIV/0!
B15: Management adjustments
A16: =B16 -> [Input adjustment] | B16: [Input adjustment] | C16: 1 | D16: =SUMIFS($J16:$AP16,$J$5:$AP$5,">"&EOMONTH(D$5,-12),$J$5:$AP$5,"<="&D$5) -> 0 | E16: =SUMIFS($J16:$AP16,$J$5:$AP$5,">"&EOMONTH(E$5,-12),$J$5:$AP$5,"<="&E$5) -> 0 | F16: =SUMIFS($J16:$AP16,$J$5:$AP$5,">"&EOMONTH(F$5,-12),$J$5:$AP$5,"<="&F$5) -> 0 | G16: =SUMIFS($J16:$AS16,$J$5:$AS$5,">"&EOMONTH(G$5,-9),$J$5:$AS$5,"<="&G$5) -> 0 | H16: =SUMIFS($J16:$AS16,$J$5:$AS$5,">"&EOMONTH(H$5,-9),$J$5:$AS$5,"<="&H$5) -> 0 | J16: ='QE Detail - MGMT.'!H16 -> 0 | K16: ='QE Detail - MGMT.'!I16 -> 0 | L16: ='QE Detail - MGMT.'!J16 -> 0 | M16: ='QE Detail - MGMT.'!K16 -> 0 | N16: ='QE Detail - MGMT.'!L16 -> 0 | O16: ='QE Detail - MGMT.'!M16 -> 0 | P16: ='QE Detail - MGMT.'!N16 -> 0 | Q16: ='QE Detail - MGMT.'!O16 -> 0 | ... AK16: ='QE Detail - MGMT.'!AI16 -> 0 | AL16: ='QE Detail - MGMT.'!AO16 -> 0 | AM16: ='QE Detail - MGMT.'!AP16 -> 0 | AN16: ='QE Detail - MGMT.'!AQ16 -> 0 | AO16: ='QE Detail - MGMT.'!AR16 -> 0 | AP16: ='QE Detail - MGMT.'!AS16 -> 0
A17: =B17 -> [Input adjustment] | B17: [Input adjustment] | C17: =+C16+1 -> 2 | D17: =SUMIFS($J17:$AP17,$J$5:$AP$5,">"&EOMONTH(D$5,-12),$J$5:$AP$5,"<="&D$5) -> 0 | E17: =SUMIFS($J17:$AP17,$J$5:$AP$5,">"&EOMONTH(E$5,-12),$J$5:$AP$5,"<="&E$5) -> 0 | F17: =SUMIFS($J17:$AP17,$J$5:$AP$5,">"&EOMONTH(F$5,-12),$J$5:$AP$5,"<="&F$5) -> 0 | G17: =SUMIFS($J17:$AS17,$J$5:$AS$5,">"&EOMONTH(G$5,-9),$J$5:$AS$5,"<="&G$5) -> 0 | H17: =SUMIFS($J17:$AS17,$J$5:$AS$5,">"&EOMONTH(H$5,-9),$J$5:$AS$5,"<="&H$5) -> 0 | J17: ='QE Detail - MGMT.'!H22 -> 0 | K17: ='QE Detail - MGMT.'!I22 -> 0 | L17: ='QE Detail - MGMT.'!J22 -> 0 | M17: ='QE Detail - MGMT.'!K22 -> 0 | N17: ='QE Detail - MGMT.'!L22 -> 0 | O17: ='QE Detail - MGMT.'!M22 -> 0 | P17: ='QE Detail - MGMT.'!N22 -> 0 | Q17: ='QE Detail - MGMT.'!O22 -> 0 | ... AK17: ='QE Detail - MGMT.'!AI22 -> 0 | AL17: ='QE Detail - MGMT.'!AO22 -> 0 | AM17: ='QE Detail - MGMT.'!AP22 -> 0 | AN17: ='QE Detail - MGMT.'!AQ22 -> 0 | AO17: ='QE Detail - MGMT.'!AR22 -> 0 | AP17: ='QE Detail - MGMT.'!AS22 -> 0
A18: =B18 -> [Input adjustment] | B18: [Input adjustment] | C18: =+C17+1 -> 3 | D18: =SUMIFS($J18:$AP18,$J$5:$AP$5,">"&EOMONTH(D$5,-12),$J$5:$AP$5,"<="&D$5) -> 0 | E18: =SUMIFS($J18:$AP18,$J$5:$AP$5,">"&EOMONTH(E$5,-12),$J$5:$AP$5,"<="&E$5) -> 0 | F18: =SUMIFS($J18:$AP18,$J$5:$AP$5,">"&EOMONTH(F$5,-12),$J$5:$AP$5,"<="&F$5) -> 0 | G18: =SUMIFS($J18:$AS18,$J$5:$AS$5,">"&EOMONTH(G$5,-9),$J$5:$AS$5,"<="&G$5) -> 0 | H18: =SUMIFS($J18:$AS18,$J$5:$AS$5,">"&EOMONTH(H$5,-9),$J$5:$AS$5,"<="&H$5) -> 0 | J18: ='QE Detail - MGMT.'!H37 -> 0 | K18: ='QE Detail - MGMT.'!I37 -> 0 | L18: ='QE Detail - MGMT.'!J37 -> 0 | M18: ='QE Detail - MGMT.'!K37 -> 0 | N18: ='QE Detail - MGMT.'!L37 -> 0 | O18: ='QE Detail - MGMT.'!M37 -> 0 | P18: ='QE Detail - MGMT.'!N37 -> 0 | Q18: ='QE Detail - MGMT.'!O37 -> 0 | ... AK18: ='QE Detail - MGMT.'!AI37 -> 0 | AL18: ='QE Detail - MGMT.'!AO37 -> 0 | AM18: ='QE Detail - MGMT.'!AP37 -> 0 | AN18: ='QE Detail - MGMT.'!AQ37 -> 0 | AO18: ='QE Detail - MGMT.'!AR37 -> 0 | AP18: ='QE Detail - MGMT.'!AS37 -> 0
A19: =B19 -> [Input adjustment] | B19: [Input adjustment] | C19: =+C18+1 -> 4 | D19: =SUMIFS($J19:$AP19,$J$5:$AP$5,">"&EOMONTH(D$5,-12),$J$5:$AP$5,"<="&D$5) -> 0 | E19: =SUMIFS($J19:$AP19,$J$5:$AP$5,">"&EOMONTH(E$5,-12),$J$5:$AP$5,"<="&E$5) -> 0 | F19: =SUMIFS($J19:$AP19,$J$5:$AP$5,">"&EOMONTH(F$5,-12),$J$5:$AP$5,"<="&F$5) -> 0 | G19: =SUMIFS($J19:$AS19,$J$5:$AS$5,">"&EOMONTH(G$5,-9),$J$5:$AS$5,"<="&G$5) -> 0 | H19: =SUMIFS($J19:$AS19,$J$5:$AS$5,">"&EOMONTH(H$5,-9),$J$5:$AS$5,"<="&H$5) -> 0 | J19: ='QE Detail - MGMT.'!H46 -> 0 | K19: ='QE Detail - MGMT.'!I46 -> 0 | L19: ='QE Detail - MGMT.'!J46 -> 0 | M19: ='QE Detail - MGMT.'!K46 -> 0 | N19: ='QE Detail - MGMT.'!L46 -> 0 | O19: ='QE Detail - MGMT.'!M46 -> 0 | P19: ='QE Detail - MGMT.'!N46 -> 0 | Q19: ='QE Detail - MGMT.'!O46 -> 0 | ... AK19: ='QE Detail - MGMT.'!AI46 -> 0 | AL19: ='QE Detail - MGMT.'!AO46 -> 0 | AM19: ='QE Detail - MGMT.'!AP46 -> 0 | AN19: ='QE Detail - MGMT.'!AQ46 -> 0 | AO19: ='QE Detail - MGMT.'!AR46 -> 0 | AP19: ='QE Detail - MGMT.'!AS46 -> 0
A20: =B20 -> [Input adjustment] | B20: [Input adjustment] | C20: =+C19+1 -> 5 | D20: =SUMIFS($J20:$AP20,$J$5:$AP$5,">"&EOMONTH(D$5,-12),$J$5:$AP$5,"<="&D$5) -> 0 | E20: =SUMIFS($J20:$AP20,$J$5:$AP$5,">"&EOMONTH(E$5,-12),$J$5:$AP$5,"<="&E$5) -> 0 | F20: =SUMIFS($J20:$AP20,$J$5:$AP$5,">"&EOMONTH(F$5,-12),$J$5:$AP$5,"<="&F$5) -> 0 | G20: =SUMIFS($J20:$AS20,$J$5:$AS$5,">"&EOMONTH(G$5,-9),$J$5:$AS$5,"<="&G$5) -> 0 | H20: =SUMIFS($J20:$AS20,$J$5:$AS$5,">"&EOMONTH(H$5,-9),$J$5:$AS$5,"<="&H$5) -> 0 | J20: ='QE Detail - MGMT.'!H57 -> 0 | K20: ='QE Detail - MGMT.'!I57 -> 0 | L20: ='QE Detail - MGMT.'!J57 -> 0 | M20: ='QE Detail - MGMT.'!K57 -> 0 | N20: ='QE Detail - MGMT.'!L57 -> 0 | O20: ='QE Detail - MGMT.'!M57 -> 0 | P20: ='QE Detail - MGMT.'!N57 -> 0 | Q20: ='QE Detail - MGMT.'!O57 -> 0 | ... AK20: ='QE Detail - MGMT.'!AI57 -> 0 | AL20: ='QE Detail - MGMT.'!AO57 -> 0 | AM20: ='QE Detail - MGMT.'!AP57 -> 0 | AN20: ='QE Detail - MGMT.'!AQ57 -> 0 | AO20: ='QE Detail - MGMT.'!AR57 -> 0 | AP20: ='QE Detail - MGMT.'!AS57 -> 0
A21: =B21 -> [Input adjustment] | B21: [Input adjustment] | C21: =+C20+1 -> 6 | D21: =SUMIFS($J21:$AP21,$J$5:$AP$5,">"&EOMONTH(D$5,-12),$J$5:$AP$5,"<="&D$5) -> 0 | E21: =SUMIFS($J21:$AP21,$J$5:$AP$5,">"&EOMONTH(E$5,-12),$J$5:$AP$5,"<="&E$5) -> 0 | F21: =SUMIFS($J21:$AP21,$J$5:$AP$5,">"&EOMONTH(F$5,-12),$J$5:$AP$5,"<="&F$5) -> 0 | G21: =SUMIFS($J21:$AS21,$J$5:$AS$5,">"&EOMONTH(G$5,-9),$J$5:$AS$5,"<="&G$5) -> 0 | H21: =SUMIFS($J21:$AS21,$J$5:$AS$5,">"&EOMONTH(H$5,-9),$J$5:$AS$5,"<="&H$5) -> 0 | J21: ='QE Detail - MGMT.'!H64 -> 0 | K21: ='QE Detail - MGMT.'!I64 -> 0 | L21: ='QE Detail - MGMT.'!J64 -> 0 | M21: ='QE Detail - MGMT.'!K64 -> 0 | N21: ='QE Detail - MGMT.'!L64 -> 0 | O21: ='QE Detail - MGMT.'!M64 -> 0 | P21: ='QE Detail - MGMT.'!N64 -> 0 | Q21: ='QE Detail - MGMT.'!O64 -> 0 | ... AK21: ='QE Detail - MGMT.'!AI64 -> 0 | AL21: ='QE Detail - MGMT.'!AO64 -> 0 | AM21: ='QE Detail - MGMT.'!AP64 -> 0 | AN21: ='QE Detail - MGMT.'!AQ64 -> 0 | AO21: ='QE Detail - MGMT.'!AR64 -> 0 | AP21: ='QE Detail - MGMT.'!AS64 -> 0
A22: =B22 -> [Input adjustment] | B22: [Input adjustment] | C22: =+C21+1 -> 7 | D22: =SUMIFS($J22:$AP22,$J$5:$AP$5,">"&EOMONTH(D$5,-12),$J$5:$AP$5,"<="&D$5) -> 0 | E22: =SUMIFS($J22:$AP22,$J$5:$AP$5,">"&EOMONTH(E$5,-12),$J$5:$AP$5,"<="&E$5) -> 0 | F22: =SUMIFS($J22:$AP22,$J$5:$AP$5,">"&EOMONTH(F$5,-12),$J$5:$AP$5,"<="&F$5) -> 0 | G22: =SUMIFS($J22:$AS22,$J$5:$AS$5,">"&EOMONTH(G$5,-9),$J$5:$AS$5,"<="&G$5) -> 0 | H22: =SUMIFS($J22:$AS22,$J$5:$AS$5,">"&EOMONTH(H$5,-9),$J$5:$AS$5,"<="&H$5) -> 0 | J22: ='QE Detail - MGMT.'!H70 -> 0 | K22: ='QE Detail - MGMT.'!I70 -> 0 | L22: ='QE Detail - MGMT.'!J70 -> 0 | M22: ='QE Detail - MGMT.'!K70 -> 0 | N22: ='QE Detail - MGMT.'!L70 -> 0 | O22: ='QE Detail - MGMT.'!M70 -> 0 | P22: ='QE Detail - MGMT.'!N70 -> 0 | Q22: ='QE Detail - MGMT.'!O70 -> 0 | ... AK22: ='QE Detail - MGMT.'!AI70 -> 0 | AL22: ='QE Detail - MGMT.'!AO70 -> 0 | AM22: ='QE Detail - MGMT.'!AP70 -> 0 | AN22: ='QE Detail - MGMT.'!AQ70 -> 0 | AO22: ='QE Detail - MGMT.'!AR70 -> 0 | AP22: ='QE Detail - MGMT.'!AS70 -> 0
A23: =B23 -> [Input adjustment] | B23: [Input adjustment] | C23: =+C22+1 -> 8 | D23: =SUMIFS($J23:$AP23,$J$5:$AP$5,">"&EOMONTH(D$5,-12),$J$5:$AP$5,"<="&D$5) -> 0 | E23: =SUMIFS($J23:$AP23,$J$5:$AP$5,">"&EOMONTH(E$5,-12),$J$5:$AP$5,"<="&E$5) -> 0 | F23: =SUMIFS($J23:$AP23,$J$5:$AP$5,">"&EOMONTH(F$5,-12),$J$5:$AP$5,"<="&F$5) -> 0 | G23: =SUMIFS($J23:$AS23,$J$5:$AS$5,">"&EOMONTH(G$5,-9),$J$5:$AS$5,"<="&G$5) -> 0 | H23: =SUMIFS($J23:$AS23,$J$5:$AS$5,">"&EOMONTH(H$5,-9),$J$5:$AS$5,"<="&H$5) -> 0 | J23: ='QE Detail - MGMT.'!H77 -> 0 | K23: ='QE Detail - MGMT.'!I77 -> 0 | L23: ='QE Detail - MGMT.'!J77 -> 0 | M23: ='QE Detail - MGMT.'!K77 -> 0 | N23: ='QE Detail - MGMT.'!L77 -> 0 | O23: ='QE Detail - MGMT.'!M77 -> 0 | P23: ='QE Detail - MGMT.'!N77 -> 0 | Q23: ='QE Detail - MGMT.'!O77 -> 0 | ... AK23: ='QE Detail - MGMT.'!AI77 -> 0 | AL23: ='QE Detail - MGMT.'!AO77 -> 0 | AM23: ='QE Detail - MGMT.'!AP77 -> 0 | AN23: ='QE Detail - MGMT.'!AQ77 -> 0 | AO23: ='QE Detail - MGMT.'!AR77 -> 0 | AP23: ='QE Detail - MGMT.'!AS77 -> 0
A24: =B24 -> [Input adjustment] | B24: [Input adjustment] | C24: =+C23+1 -> 9 | D24: =SUMIFS($J24:$AP24,$J$5:$AP$5,">"&EOMONTH(D$5,-12),$J$5:$AP$5,"<="&D$5) -> 0 | E24: =SUMIFS($J24:$AP24,$J$5:$AP$5,">"&EOMONTH(E$5,-12),$J$5:$AP$5,"<="&E$5) -> 0 | F24: =SUMIFS($J24:$AP24,$J$5:$AP$5,">"&EOMONTH(F$5,-12),$J$5:$AP$5,"<="&F$5) -> 0 | G24: =SUMIFS($J24:$AS24,$J$5:$AS$5,">"&EOMONTH(G$5,-9),$J$5:$AS$5,"<="&G$5) -> 0 | H24: =SUMIFS($J24:$AS24,$J$5:$AS$5,">"&EOMONTH(H$5,-9),$J$5:$AS$5,"<="&H$5) -> 0 | J24: ='QE Detail - MGMT.'!H83 -> 0 | K24: ='QE Detail - MGMT.'!I83 -> 0 | L24: ='QE Detail - MGMT.'!J83 -> 0 | M24: ='QE Detail - MGMT.'!K83 -> 0 | N24: ='QE Detail - MGMT.'!L83 -> 0 | O24: ='QE Detail - MGMT.'!M83 -> 0 | P24: ='QE Detail - MGMT.'!N83 -> 0 | Q24: ='QE Detail - MGMT.'!O83 -> 0 | ... AK24: ='QE Detail - MGMT.'!AI83 -> 0 | AL24: ='QE Detail - MGMT.'!AO83 -> 0 | AM24: ='QE Detail - MGMT.'!AP83 -> 0 | AN24: ='QE Detail - MGMT.'!AQ83 -> 0 | AO24: ='QE Detail - MGMT.'!AR83 -> 0 | AP24: ='QE Detail - MGMT.'!AS83 -> 0
A25: =B25 -> [Input adjustment] | B25: [Input adjustment] | C25: =+C24+1 -> 10 | D25: =SUMIFS($J25:$AP25,$J$5:$AP$5,">"&EOMONTH(D$5,-12),$J$5:$AP$5,"<="&D$5) -> 0 | E25: =SUMIFS($J25:$AP25,$J$5:$AP$5,">"&EOMONTH(E$5,-12),$J$5:$AP$5,"<="&E$5) -> 0 | F25: =SUMIFS($J25:$AP25,$J$5:$AP$5,">"&EOMONTH(F$5,-12),$J$5:$AP$5,"<="&F$5) -> 0 | G25: =SUMIFS($J25:$AS25,$J$5:$AS$5,">"&EOMONTH(G$5,-9),$J$5:$AS$5,"<="&G$5) -> 0 | H25: =SUMIFS($J25:$AS25,$J$5:$AS$5,">"&EOMONTH(H$5,-9),$J$5:$AS$5,"<="&H$5) -> 0 | J25: ='QE Detail - MGMT.'!H91 -> 0 | K25: ='QE Detail - MGMT.'!I91 -> 0 | L25: ='QE Detail - MGMT.'!J91 -> 0 | M25: ='QE Detail - MGMT.'!K91 -> 0 | N25: ='QE Detail - MGMT.'!L91 -> 0 | O25: ='QE Detail - MGMT.'!M91 -> 0 | P25: ='QE Detail - MGMT.'!N91 -> 0 | Q25: ='QE Detail - MGMT.'!O91 -> 0 | ... AK25: ='QE Detail - MGMT.'!AI91 -> 0 | AL25: ='QE Detail - MGMT.'!AO91 -> 0 | AM25: ='QE Detail - MGMT.'!AP91 -> 0 | AN25: ='QE Detail - MGMT.'!AQ91 -> 0 | AO25: ='QE Detail - MGMT.'!AR91 -> 0 | AP25: ='QE Detail - MGMT.'!AS91 -> 0
B26: Total management adjustments | D26: =SUM(D16:D25) -> 0 | E26: =SUM(E16:E25) -> 0 | F26: =SUM(F16:F25) -> 0 | G26: =SUM(G16:G25) -> 0 | H26: =SUM(H16:H25) -> 0 | J26: =SUM(J16:J25) -> 0 | K26: =SUM(K16:K25) -> 0 | L26: =SUM(L16:L25) -> 0 | M26: =SUM(M16:M25) -> 0 | N26: =SUM(N16:N25) -> 0 | O26: =SUM(O16:O25) -> 0 | P26: =SUM(P16:P25) -> 0 | Q26: =SUM(Q16:Q25) -> 0 | ... AP26: =SUM(AP16:AP25) -> 0
B27: Management adjusted EBITDA | D27: =SUM(D12,D26) -> 0 | E27: =SUM(E12,E26) -> 0 | F27: =SUM(F12,F26) -> 0 | G27: =SUM(G12,G26) -> 0 | H27: =SUM(H12,H26) -> 0 | J27: =SUM(J12,J26) -> 0 | K27: =SUM(K12,K26) -> 0 | L27: =SUM(L12,L26) -> 0 | M27: =SUM(M12,M26) -> 0 | N27: =SUM(N12,N26) -> 0 | O27: =SUM(O12,O26) -> 0 | P27: =SUM(P12,P26) -> 0 | Q27: =SUM(Q12,Q26) -> 0 | ... AP27: =SUM(AP12,AP26) -> 0
B28: % margin | D28: =(D27/'Recast Mgmt. Adjusted'!C6)*100 -> #DIV/0! | E28: =(E27/'Recast Mgmt. Adjusted'!D6)*100 -> #DIV/0! | F28: =(F27/'Recast Mgmt. Adjusted'!E6)*100 -> #DIV/0! | G28: n/a | H28: n/a | J28: =(J27/'Recast Mgmt. Adjusted'!G6)*100 -> #DIV/0! | K28: =(K27/'Recast Mgmt. Adjusted'!H6)*100 -> #DIV/0! | L28: =(L27/'Recast Mgmt. Adjusted'!I6)*100 -> #DIV/0! | M28: =(M27/'Recast Mgmt. Adjusted'!J6)*100 -> #DIV/0! | N28: =(N27/'Recast Mgmt. Adjusted'!K6)*100 -> #DIV/0! | O28: =(O27/'Recast Mgmt. Adjusted'!L6)*100 -> #DIV/0! | P28: =(P27/'Recast Mgmt. Adjusted'!M6)*100 -> #DIV/0! | Q28: =(Q27/'Recast Mgmt. Adjusted'!N6)*100 -> #DIV/0! | ... AK28: =(AK27/'Recast Mgmt. Adjusted'!AH6)*100 -> #DIV/0! | AL28: =(AL27/'Recast Mgmt. Adjusted'!AN6)*100 -> #DIV/0! | AM28: =(AM27/'Recast Mgmt. Adjusted'!AO6)*100 -> #DIV/0! | AN28: =(AN27/'Recast Mgmt. Adjusted'!AP6)*100 -> #DIV/0! | AO28: =(AO27/'Recast Mgmt. Adjusted'!AQ6)*100 -> #DIV/0! | AP28: =(AP27/'Recast Mgmt. Adjusted'!AR6)*100 -> #DIV/0!
B30: Source: Internal financials provided by Management & STOC analysis

Sheet QE Descriptions
A1: =Project&" - "&City&", "&State -> OPEN - OPEN, OPEN
A2: =MID(CELL("filename",A1),FIND("]",CELL("filename",A1))+1,255) -> QE Descriptions
A4: Overview: Reported EBITDA was calculated as net income plus interest expense, amortization, and depreciation expense. Management adjustments consist of the amounts presented in the LOI. Due diligence adjustments consist of various items considered to be one-time, non-recurring, inconsistent with GAAP, out-of-period, go-forward, or otherwise non-operating in nature. Pro forma adjustments relate to anticipated cost structure changes and views of certain financial conditions, as if they were present throughout the entire Historical Period. We analyzed the Company's financial records and held discussions with Management to understand the circumstances of each adjustment. Unless specifically noted, we corroborated these adjustments with detailed trial balance information and other supporting documentation.
A9: Adjustment | B9: Description
A10: =CONCATENATE('Lead QE'!C16,") ",'Lead QE'!B16) -> 1) [Input adjustment]
A11: =CONCATENATE('Lead QE'!C17,") ",'Lead QE'!B17) -> 2) [Input adjustment]
A12: =CONCATENATE('Lead QE'!C18,") ",'Lead QE'!B18) -> 3) [Input adjustment]
A13: =CONCATENATE('Lead QE'!C19,") ",'Lead QE'!B19) -> 4) [Input adjustment]
A14: =CONCATENATE('Lead QE'!C20,") ",'Lead QE'!B20) -> 5) [Input adjustment]
A15: =CONCATENATE('Lead QE'!C21,") ",'Lead QE'!B21) -> 6) [Input adjustment]
A16: =CONCATENATE('Lead QE'!C22,") ",'Lead QE'!B22) -> 7) [Input adjustment]
A17: =CONCATENATE('Lead QE'!C23,") ",'Lead QE'!B23) -> 8) [Input adjustment]
A18: =CONCATENATE('Lead QE'!C24,") ",'Lead QE'!B24) -> 9) [Input adjustment]
A19: =CONCATENATE('Lead QE'!C25,") ",'Lead QE'!B25) -> 10) [Input adjustment]

Sheet QE Detail - MGMT.
C1: =Project&" - "&City&", "&State -> OPEN - OPEN, OPEN
C2: =MID(CELL("filename",C1),FIND("]",CELL("filename",C1))+1,255) -> QE Detail - MGMT.
A4: PnL | B4: Recast PL Account Mapping | C4: =CONCATENATE('Lead QE'!C16,") ",'Lead QE'!B16) -> 1) [Input adjustment]
C5: In $000's | D5: =First_Reporting_Year -> 44926 | E5: =Second_Reporting_Year -> 45291 | F5: =Stub_Period -> 45565 | H5: =EOMONTH(D5,-11) -> 44592 | I5: =EOMONTH(H5,1) -> 44620 | J5: =EOMONTH(I5,1) -> 44651 | K5: =EOMONTH(J5,1) -> 44681 | L5: =EOMONTH(K5,1) -> 44712 | M5: =EOMONTH(L5,1) -> 44742 | N5: =EOMONTH(M5,1) -> 44773 | O5: =EOMONTH(N5,1) -> 44804 | P5: =EOMONTH(O5,1) -> 44834 | ... AN5: =EOMONTH(AM5,1) -> 45565
C16: EBITDA adjustment | D16: =D9+D15 -> 0 | E16: =E9+E15 -> 0 | F16: =F9+F15 -> 0 | H16: =H9+H15 -> 0 | I16: =I9+I15 -> 0 | J16: =J9+J15 -> 0 | K16: =K9+K15 -> 0 | L16: =L9+L15 -> 0 | M16: =M9+M15 -> 0 | N16: =N9+N15 -> 0 | O16: =O9+O15 -> 0 | ... AN16: =AN9+AN15 -> 0
C17: Source: Internal financials provided by Management & STOC analysis
C19: =CONCATENATE('Lead QE'!C17,") ",'Lead QE'!B17) -> 2) [Input adjustment]
C20: In $000's | D20: =First_Reporting_Year -> 44926 | E20: =Second_Reporting_Year -> 45291 | F20: =Stub_Period -> 45565 | H20: =EOMONTH(D20,-11) -> 44592 | I20: =EOMONTH(H20,1) -> 44620 | J20: =EOMONTH(I20,1) -> 44651 | K20: =EOMONTH(J20,1) -> 44681 | L20: =EOMONTH(K20,1) -> 44712 | M20: =EOMONTH(L20,1) -> 44742 | N20: =EOMONTH(M20,1) -> 44773 | O20: =EOMONTH(N20,1) -> 44804 | P20: =EOMONTH(O20,1) -> 44834 | ... AN20: =EOMONTH(AM20,1) -> 45565
B22: Other | C22: EBITDA adjustment | D22: =SUM(D21:D21) -> 0 | E22: =SUM(E21:E21) -> 0 | F22: =SUM(F21:F21) -> 0 | G22: =SUM(G21:G21) -> 0 | H22: =SUM(H21:H21) -> 0 | I22: =SUM(I21:I21) -> 0 | J22: =SUM(J21:J21) -> 0 | K22: =SUM(K21:K21) -> 0 | ... AN22: =SUM(AN21:AN21) -> 0
C23: Source: Internal financials provided by Management & STOC analysis
C25: =CONCATENATE('Lead QE'!C18,") ",'Lead QE'!B18) -> 3) [Input adjustment]
C26: In $000's | D26: =First_Reporting_Year -> 44926 | E26: =Second_Reporting_Year -> 45291 | F26: =Stub_Period -> 45565 | H26: =EOMONTH(D26,-11) -> 44592 | I26: =EOMONTH(H26,1) -> 44620 | J26: =EOMONTH(I26,1) -> 44651 | K26: =EOMONTH(J26,1) -> 44681 | L26: =EOMONTH(K26,1) -> 44712 | M26: =EOMONTH(L26,1) -> 44742 | N26: =EOMONTH(M26,1) -> 44773 | O26: =EOMONTH(N26,1) -> 44804 | P26: =EOMONTH(O26,1) -> 44834 | ... AN26: =EOMONTH(AM26,1) -> 45565
C36: Total go-forward [B] | D36: =SUM(D34:D35) -> 0 | E36: =SUM(E34:E35) -> 0 | F36: =SUM(F34:F35) -> 0 | H36: =SUM(H34:H35) -> 0 | I36: =SUM(I34:I35) -> 0 | J36: =SUM(J34:J35) -> 0 | K36: =SUM(K34:K35) -> 0 | L36: =SUM(L34:L35) -> 0 | M36: =SUM(M34:M35) -> 0 | N36: =SUM(N34:N35) -> 0 | O36: =SUM(O34:O35) -> 0 | ... AN36: =SUM(AN34:AN35) -> 0
C37: EBITDA adjustment [A] - [B] | D37: =D31-D36 -> 0 | E37: =E31-E36 -> 0 | F37: =F31-F36 -> 0 | G37: =G31-G36 -> 0 | H37: =H31-H36 -> 0 | I37: =I31-I36 -> 0 | J37: =J31-J36 -> 0 | K37: =K31-K36 -> 0 | ... AN37: =AN31-AN36 -> 0
C38: Source: Internal financials provided by Management & STOC analysis
B39: Insurance | C39: Insurance | D39: =SUMIFS($H39:$AN39,$H$5:$AN$5,">"&EOMONTH(D$5,-12),$H$5:$AN$5,"<="&D$5) -> 0 | E39: =SUMIFS($H39:$AN39,$H$5:$AN$5,">"&EOMONTH(E$5,-12),$H$5:$AN$5,"<="&E$5) -> 0 | F39: =SUMIFS($H39:$AQ39,$H$5:$AQ$5,">"&EOMONTH(F$5,-12),$H$5:$AQ$5,"<="&F$5) -> 0 | H39: =H29-H34 -> 0 | I39: =I29-I34 -> 0 | J39: =J29-J34 -> 0 | K39: =K29-K34 -> 0 | L39: =L29-L34 -> 0 | M39: =M29-M34 -> 0 | N39: =N29-N34 -> 0 | O39: =O29-O34 -> 0 | ... AN39: =AN29-AN34 -> 0
B40: Employee 401(k) | C40: Employee 401(k) | D40: =SUMIFS($H40:$AN40,$H$5:$AN$5,">"&EOMONTH(D$5,-12),$H$5:$AN$5,"<="&D$5) -> 0 | E40: =SUMIFS($H40:$AN40,$H$5:$AN$5,">"&EOMONTH(E$5,-12),$H$5:$AN$5,"<="&E$5) -> 0 | F40: =SUMIFS($H40:$AQ40,$H$5:$AQ$5,">"&EOMONTH(F$5,-12),$H$5:$AQ$5,"<="&F$5) -> 0 | H40: =H30-H35 -> 0 | I40: =I30-I35 -> 0 | J40: =J30-J35 -> 0 | K40: =K30-K35 -> 0 | L40: =L30-L35 -> 0 | M40: =M30-M35 -> 0 | N40: =N30-N35 -> 0 | O40: =O30-O35 -> 0 | ... AN40: =AN30-AN35 -> 0
C42: =CONCATENATE('Lead QE'!C19,") ",'Lead QE'!B19) -> 4) [Input adjustment]
C43: In $000's | D43: =First_Reporting_Year -> 44926 | E43: =Second_Reporting_Year -> 45291 | F43: =Stub_Period -> 45565 | H43: =EOMONTH(D43,-11) -> 44592 | I43: =EOMONTH(H43,1) -> 44620 | J43: =EOMONTH(I43,1) -> 44651 | K43: =EOMONTH(J43,1) -> 44681 | L43: =EOMONTH(K43,1) -> 44712 | M43: =EOMONTH(L43,1) -> 44742 | N43: =EOMONTH(M43,1) -> 44773 | O43: =EOMONTH(N43,1) -> 44804 | P43: =EOMONTH(O43,1) -> 44834 | ... AN43: =EOMONTH(AM43,1) -> 45565
D44: =SUMIFS($H44:$AN44,$H$5:$AN$5,">"&EOMONTH(D$5,-12),$H$5:$AN$5,"<="&D$5) -> 0 | E44: =SUMIFS($H44:$AN44,$H$5:$AN$5,">"&EOMONTH(E$5,-12),$H$5:$AN$5,"<="&E$5) -> 0 | F44: =SUMIFS($H44:$AQ44,$H$5:$AQ$5,">"&EOMONTH(F$5,-12),$H$5:$AQ$5,"<="&F$5) -> 0
D45: =SUMIFS($H45:$AN45,$H$5:$AN$5,">"&EOMONTH(D$5,-12),$H$5:$AN$5,"<="&D$5) -> 0 | E45: =SUMIFS($H45:$AN45,$H$5:$AN$5,">"&EOMONTH(E$5,-12),$H$5:$AN$5,"<="&E$5) -> 0 | F45: =SUMIFS($H45:$AQ45,$H$5:$AQ$5,">"&EOMONTH(F$5,-12),$H$5:$AQ$5,"<="&F$5) -> 0
B46: Other | C46: EBITDA adjustment | D46: =SUM(D44:D45) -> 0 | E46: =SUM(E44:E45) -> 0 | F46: =SUM(F44:F45) -> 0 | H46: =SUM(H44:H45) -> 0 | I46: =SUM(I44:I45) -> 0 | J46: =SUM(J44:J45) -> 0 | K46: =SUM(K44:K45) -> 0 | L46: =SUM(L44:L45) -> 0 | M46: =SUM(M44:M45) -> 0 | N46: =SUM(N44:N45) -> 0 | O46: =SUM(O44:O45) -> 0 | ... AN46: =SUM(AN44:AN45) -> 0
C47: Source: Internal financials provided by Management & STOC analysis
C49: =CONCATENATE('Lead QE'!C20,") ",'Lead QE'!B20) -> 5) [Input adjustment]
C50: In $000's | D50: =First_Reporting_Year -> 44926 | E50: =Second_Reporting_Year -> 45291 | F50: =Stub_Period -> 45565 | H50: =EOMONTH(D50,-11) -> 44592 | I50: =EOMONTH(H50,1) -> 44620 | J50: =EOMONTH(I50,1) -> 44651 | K50: =EOMONTH(J50,1) -> 44681 | L50: =EOMONTH(K50,1) -> 44712 | M50: =EOMONTH(L50,1) -> 44742 | N50: =EOMONTH(M50,1) -> 44773 | O50: =EOMONTH(N50,1) -> 44804 | P50: =EOMONTH(O50,1) -> 44834 | ... AN50: =EOMONTH(AM50,1) -> 45565
A51: Meals and Entertainment | B51: Other | D51: =SUMIFS($H51:$AN51,$H$5:$AN$5,">"&EOMONTH(D$5,-12),$H$5:$AN$5,"<="&D$5) -> 0 | E51: =SUMIFS($H51:$AN51,$H$5:$AN$5,">"&EOMONTH(E$5,-12),$H$5:$AN$5,"<="&E$5) -> 0 | F51: =SUMIFS($H51:$AQ51,$H$5:$AQ$5,">"&EOMONTH(F$5,-12),$H$5:$AQ$5,"<="&F$5) -> 0
B52: Other | D52: =SUMIFS($H52:$AN52,$H$5:$AN$5,">"&EOMONTH(D$5,-12),$H$5:$AN$5,"<="&D$5) -> 0 | E52: =SUMIFS($H52:$AN52,$H$5:$AN$5,">"&EOMONTH(E$5,-12),$H$5:$AN$5,"<="&E$5) -> 0 | F52: =SUMIFS($H52:$AQ52,$H$5:$AQ$5,">"&EOMONTH(F$5,-12),$H$5:$AQ$5,"<="&F$5) -> 0
B53: Other | D53: =SUMIFS($H53:$AN53,$H$5:$AN$5,">"&EOMONTH(D$5,-12),$H$5:$AN$5,"<="&D$5) -> 0 | E53: =SUMIFS($H53:$AN53,$H$5:$AN$5,">"&EOMONTH(E$5,-12),$H$5:$AN$5,"<="&E$5) -> 0 | F53: =SUMIFS($H53:$AQ53,$H$5:$AQ$5,">"&EOMONTH(F$5,-12),$H$5:$AQ$5,"<="&F$5) -> 0
B54: Other | D54: =SUMIFS($H54:$AN54,$H$5:$AN$5,">"&EOMONTH(D$5,-12),$H$5:$AN$5,"<="&D$5) -> 0 | E54: =SUMIFS($H54:$AN54,$H$5:$AN$5,">"&EOMONTH(E$5,-12),$H$5:$AN$5,"<="&E$5) -> 0 | F54: =SUMIFS($H54:$AQ54,$H$5:$AQ$5,">"&EOMONTH(F$5,-12),$H$5:$AQ$5,"<="&F$5) -> 0
B55: Other | D55: =SUMIFS($H55:$AN55,$H$5:$AN$5,">"&EOMONTH(D$5,-12),$H$5:$AN$5,"<="&D$5) -> 0 | E55: =SUMIFS($H55:$AN55,$H$5:$AN$5,">"&EOMONTH(E$5,-12),$H$5:$AN$5,"<="&E$5) -> 0 | F55: =SUMIFS($H55:$AQ55,$H$5:$AQ$5,">"&EOMONTH(F$5,-12),$H$5:$AQ$5,"<="&F$5) -> 0
B56: Other | D56: =SUMIFS($H56:$AN56,$H$5:$AN$5,">"&EOMONTH(D$5,-12),$H$5:$AN$5,"<="&D$5) -> 0 | E56: =SUMIFS($H56:$AN56,$H$5:$AN$5,">"&EOMONTH(E$5,-12),$H$5:$AN$5,"<="&E$5) -> 0 | F56: =SUMIFS($H56:$AQ56,$H$5:$AQ$5,">"&EOMONTH(F$5,-12),$H$5:$AQ$5,"<="&F$5) -> 0
C57: EBITDA adjustment [A] + [B] | D57: =SUM(D51:D56) -> 0 | E57: =SUM(E51:E56) -> 0 | F57: =SUM(F51:F56) -> 0 | H57: =SUM(H51:H56) -> 0 | I57: =SUM(I51:I56) -> 0 | J57: =SUM(J51:J56) -> 0 | K57: =SUM(K51:K56) -> 0 | L57: =SUM(L51:L56) -> 0 | M57: =SUM(M51:M56) -> 0 | N57: =SUM(N51:N56) -> 0 | O57: =SUM(O51:O56) -> 0 | ... AN57: =SUM(AN51:AN56) -> 0
C58: Source: Internal financials provided by Management & STOC analysis
C60: =CONCATENATE('Lead QE'!C21,") ",'Lead QE'!B21) -> 6) [Input adjustment]
C61: In $000's | D61: =First_Reporting_Year -> 44926 | E61: =Second_Reporting_Year -> 45291 | F61: =Stub_Period -> 45565 | H61: =EOMONTH(D61,-11) -> 44592 | I61: =EOMONTH(H61,1) -> 44620 | J61: =EOMONTH(I61,1) -> 44651 | K61: =EOMONTH(J61,1) -> 44681 | L61: =EOMONTH(K61,1) -> 44712 | M61: =EOMONTH(L61,1) -> 44742 | N61: =EOMONTH(M61,1) -> 44773 | O61: =EOMONTH(N61,1) -> 44804 | P61: =EOMONTH(O61,1) -> 44834 | ... AN61: =EOMONTH(AM61,1) -> 45565
B64: Payroll taxes | C64: EBITDA adjustment | D64: =SUM(D62:D63) -> 0 | E64: =SUM(E62:E63) -> 0 | F64: =SUM(F62:F63) -> 0 | G64: =SUM(G62:G63) -> 0 | H64: =SUM(H62:H63) -> 0 | I64: =SUM(I62:I63) -> 0 | J64: =SUM(J62:J63) -> 0 | K64: =SUM(K62:K63) -> 0 | ... AN64: =SUM(AN62:AN63) -> 0
C65: Source: Internal financials provided by Management & STOC analysis
C67: =CONCATENATE('Lead QE'!C22,") ",'Lead QE'!B22) -> 7) [Input adjustment]
C68: In $000's | D68: =First_Reporting_Year -> 44926 | E68: =Second_Reporting_Year -> 45291 | F68: =Stub_Period -> 45565 | H68: =EOMONTH(D68,-11) -> 44592 | I68: =EOMONTH(H68,1) -> 44620 | J68: =EOMONTH(I68,1) -> 44651 | K68: =EOMONTH(J68,1) -> 44681 | L68: =EOMONTH(K68,1) -> 44712 | M68: =EOMONTH(L68,1) -> 44742 | N68: =EOMONTH(M68,1) -> 44773 | O68: =EOMONTH(N68,1) -> 44804 | P68: =EOMONTH(O68,1) -> 44834 | ... AN68: =EOMONTH(AM68,1) -> 45565
D69: =SUMIFS($H69:$AN69,$H$5:$AN$5,">"&EOMONTH(D$5,-12),$H$5:$AN$5,"<="&D$5) -> 0 | E69: =SUMIFS($H69:$AN69,$H$5:$AN$5,">"&EOMONTH(E$5,-12),$H$5:$AN$5,"<="&E$5) -> 0 | F69: =SUMIFS($H69:$AQ69,$H$5:$AQ$5,">"&EOMONTH(F$5,-12),$H$5:$AQ$5,"<="&F$5) -> 0
...

Sheet Recast PLs >>>
A10: =RIGHT(CELL("filename",A1),LEN(CELL("filename",A1))-FIND("]",CELL("filename",A1))) -> Recast PLs >>>

Sheet Recast Reported
B1: =Project&" - "&City&", "&State -> OPEN - OPEN, OPEN
B2: =MID(CELL("filename",B1),FIND("]",CELL("filename",B1))+1,255) -> Recast Reported
A4: Recast PL | B4: Summarized Reported P&L
B5: In $000's | C5: =First_Reporting_Year -> 44926 | D5: =Second_Reporting_Year -> 45291 | E5: =Stub_Period -> 45565 | G5: =EOMONTH(C5,-11) -> 44592 | H5: =EOMONTH(G5,1) -> 44620 | I5: =EOMONTH(H5,1) -> 44651 | J5: =EOMONTH(I5,1) -> 44681 | K5: =EOMONTH(J5,1) -> 44712 | L5: =EOMONTH(K5,1) -> 44742 | M5: =EOMONTH(L5,1) -> 44773 | N5: =EOMONTH(M5,1) -> 44804 | O5: =EOMONTH(N5,1) -> 44834 | ... AM5: =EOMONTH(AL5,1) -> 45565
A6: Revenue, net | B6: Revenue, net | C6: =SUMIFS($G6:$BC6,$G$5:$BC$5,"<="&EOMONTH(C$5,0),$G$6:$BC$6,"<="&C$5) -> 0 | D6: =SUMIFS($G6:$AT6,$G$5:$AT$5,">"&EOMONTH(D$5,-12),$G$5:$AT$5,"<="&D$5) -> 0 | E6: =SUMIFS($G6:$AT6,$G$5:$AT$5,">"&EOMONTH(E$5,-12),$G$5:$AT$5,"<="&E$5) -> 0 | G6: =SUMIFS(PL!L:L,PL!$B:$B,$B6) -> 0 | H6: =SUMIFS(PL!M:M,PL!$B:$B,$B6) -> 0 | I6: =SUMIFS(PL!N:N,PL!$B:$B,$B6) -> 0 | J6: =SUMIFS(PL!O:O,PL!$B:$B,$B6) -> 0 | K6: =SUMIFS(PL!P:P,PL!$B:$B,$B6) -> 0 | L6: =SUMIFS(PL!Q:Q,PL!$B:$B,$B6) -> 0 | M6: =SUMIFS(PL!R:R,PL!$B:$B,$B6) -> 0 | N6: =SUMIFS(PL!S:S,PL!$B:$B,$B6) -> 0 | O6: =SUMIFS(PL!T:T,PL!$B:$B,$B6) -> 0 | P6: =SUMIFS(PL!U:U,PL!$B:$B,$B6) -> 0 | Q6: =SUMIFS(PL!V:V,PL!$B:$B,$B6) -> 0 | R6: =SUMIFS(PL!W:W,PL!$B:$B,$B6) -> 0 | S6: =SUMIFS(PL!X:X,PL!$B:$B,$B6) -> 0 | T6: =SUMIFS(PL!Y:Y,PL!$B:$B,$B6) -> 0 | U6: =SUMIFS(PL!Z:Z,PL!$B:$B,$B6) -> 0 | V6: =SUMIFS(PL!AA:AA,PL!$B:$B,$B6) -> 0 | W6: =SUMIFS(PL!AB:AB,PL!$B:$B,$B6) -> 0 | X6: =SUMIFS(PL!AC:AC,PL!$B:$B,$B6) -> 0 | Y6: =SUMIFS(PL!AD:AD,PL!$B:$B,$B6) -> 0 | Z6: =SUMIFS(PL!AE:AE,PL!$B:$B,$B6) -> 0 | AA6: =SUMIFS(PL!AF:AF,PL!$B:$B,$B6) -> 0 | AB6: =SUMIFS(PL!AG:AG,PL!$B:$B,$B6) -> 0 | AC6: =SUMIFS(PL!AH:AH,PL!$B:$B,$B6) -> 0 | AD6: =SUMIFS(PL!AI:AI,PL!$B:$B,$B6) -> 0 | AE6: =SUMIFS(PL!AJ:AJ,PL!$B:$B,$B6) -> 0 | AF6: =SUMIFS(PL!AK:AK,PL!$B:$B,$B6) -> 0 | AG6: =SUMIFS(PL!AL:AL,PL!$B:$B,$B6) -> 0 | AH6: =SUMIFS(PL!AM:AM,PL!$B:$B,$B6) -> 0 | AI6: =SUMIFS(PL!AN:AN,PL!$B:$B,$B6) -> 0 | AJ6: =SUMIFS(PL!AS:AS,PL!$B:$B,$B6) -> 0 | AK6: =SUMIFS(PL!AT:AT,PL!$B:$B,$B6) -> 0 | AL6: =SUMIFS(PL!AU:AU,PL!$B:$B,$B6) -> 0 | AM6: =SUMIFS(PL!AV:AV,PL!$B:$B,$B6) -> 0
A7: Dental supplies | B7: Dental supplies | C7: =SUMIFS($G7:$BC7,$G$5:$BC$5,"<="&EOMONTH(C$5,0),$G$6:$BC$6,"<="&C$5) -> 0 | D7: =SUMIFS($G7:$AT7,$G$5:$AT$5,">"&EOMONTH(D$5,-12),$G$5:$AT$5,"<="&D$5) -> 0 | E7: =SUMIFS($G7:$AT7,$G$5:$AT$5,">"&EOMONTH(E$5,-12),$G$5:$AT$5,"<="&E$5) -> 0 | G7: =SUMIFS(PL!L:L,PL!$B:$B,$B7) -> 0 | H7: =SUMIFS(PL!M:M,PL!$B:$B,$B7) -> 0 | I7: =SUMIFS(PL!N:N,PL!$B:$B,$B7) -> 0 | J7: =SUMIFS(PL!O:O,PL!$B:$B,$B7) -> 0 | K7: =SUMIFS(PL!P:P,PL!$B:$B,$B7) -> 0 | L7: =SUMIFS(PL!Q:Q,PL!$B:$B,$B7) -> 0 | M7: =SUMIFS(PL!R:R,PL!$B:$B,$B7) -> 0 | N7: =SUMIFS(PL!S:S,PL!$B:$B,$B7) -> 0 | O7: =SUMIFS(PL!T:T,PL!$B:$B,$B7) -> 0 | P7: =SUMIFS(PL!U:U,PL!$B:$B,$B7) -> 0 | Q7: =SUMIFS(PL!V:V,PL!$B:$B,$B7) -> 0 | R7: =SUMIFS(PL!W:W,PL!$B:$B,$B7) -> 0 | S7: =SUMIFS(PL!X:X,PL!$B:$B,$B7) -> 0 | T7: =SUMIFS(PL!Y:Y,PL!$B:$B,$B7) -> 0 | U7: =SUMIFS(PL!Z:Z,PL!$B:$B,$B7) -> 0 | V7: =SUMIFS(PL!AA:AA,PL!$B:$B,$B7) -> 0 | W7: =SUMIFS(PL!AB:AB,PL!$B:$B,$B7) -> 0 | X7: =SUMIFS(PL!AC:AC,PL!$B:$B,$B7) -> 0 | Y7: =SUMIFS(PL!AD:AD,PL!$B:$B,$B7) -> 0 | Z7: =SUMIFS(PL!AE:AE,PL!$B:$B,$B7) -> 0 | AA7: =SUMIFS(PL!AF:AF,PL!$B:$B,$B7) -> 0 | AB7: =SUMIFS(PL!AG:AG,PL!$B:$B,$B7) -> 0 | AC7: =SUMIFS(PL!AH:AH,PL!$B:$B,$B7) -> 0 | AD7: =SUMIFS(PL!AI:AI,PL!$B:$B,$B7) -> 0 | AE7: =SUMIFS(PL!AJ:AJ,PL!$B:$B,$B7) -> 0 | AF7: =SUMIFS(PL!AK:AK,PL!$B:$B,$B7) -> 0 | AG7: =SUMIFS(PL!AL:AL,PL!$B:$B,$B7) -> 0 | AH7: =SUMIFS(PL!AM:AM,PL!$B:$B,$B7) -> 0 | AI7: =SUMIFS(PL!AN:AN,PL!$B:$B,$B7) -> 0 | AJ7: =SUMIFS(PL!AS:AS,PL!$B:$B,$B7) -> 0 | AK7: =SUMIFS(PL!AT:AT,PL!$B:$B,$B7) -> 0 | AL7: =SUMIFS(PL!AU:AU,PL!$B:$B,$B7) -> 0 | AM7: =SUMIFS(PL!AV:AV,PL!$B:$B,$B7) -> 0
A8: Ortho supplies | B8: Ortho supplies | C8: =SUMIFS($G8:$BC8,$G$5:$BC$5,"<="&EOMONTH(C$5,0),$G$6:$BC$6,"<="&C$5) -> 0 | D8: =SUMIFS($G8:$AT8,$G$5:$AT$5,">"&EOMONTH(D$5,-12),$G$5:$AT$5,"<="&D$5) -> 0 | E8: =SUMIFS($G8:$AT8,$G$5:$AT$5,">"&EOMONTH(E$5,-12),$G$5:$AT$5,"<="&E$5) -> 0 | G8: =SUMIFS(PL!L:L,PL!$B:$B,$B8) -> 0 | H8: =SUMIFS(PL!M:M,PL!$B:$B,$B8) -> 0 | I8: =SUMIFS(PL!N:N,PL!$B:$B,$B8) -> 0 | J8: =SUMIFS(PL!O:O,PL!$B:$B,$B8) -> 0 | K8: =SUMIFS(PL!P:P,PL!$B:$B,$B8) -> 0 | L8: =SUMIFS(PL!Q:Q,PL!$B:$B,$B8) -> 0 | M8: =SUMIFS(PL!R:R,PL!$B:$B,$B8) -> 0 | N8: =SUMIFS(PL!S:S,PL!$B:$B,$B8) -> 0 | O8: =SUMIFS(PL!T:T,PL!$B:$B,$B8) -> 0 | P8: =SUMIFS(PL!U:U,PL!$B:$B,$B8) -> 0 | Q8: =SUMIFS(PL!V:V,PL!$B:$B,$B8) -> 0 | R8: =SUMIFS(PL!W:W,PL!$B:$B,$B8) -> 0 | S8: =SUMIFS(PL!X:X,PL!$B:$B,$B8) -> 0 | T8: =SUMIFS(PL!Y:Y,PL!$B:$B,$B8) -> 0 | U8: =SUMIFS(PL!Z:Z,PL!$B:$B,$B8) -> 0 | V8: =SUMIFS(PL!AA:AA,PL!$B:$B,$B8) -> 0 | W8: =SUMIFS(PL!AB:AB,PL!$B:$B,$B8) -> 0 | X8: =SUMIFS(PL!AC:AC,PL!$B:$B,$B8) -> 0 | Y8: =SUMIFS(PL!AD:AD,PL!$B:$B,$B8) -> 0 | Z8: =SUMIFS(PL!AE:AE,PL!$B:$B,$B8) -> 0 | AA8: =SUMIFS(PL!AF:AF,PL!$B:$B,$B8) -> 0 | AB8: =SUMIFS(PL!AG:AG,PL!$B:$B,$B8) -> 0 | AC8: =SUMIFS(PL!AH:AH,PL!$B:$B,$B8) -> 0 | AD8: =SUMIFS(PL!AI:AI,PL!$B:$B,$B8) -> 0 | AE8: =SUMIFS(PL!AJ:AJ,PL!$B:$B,$B8) -> 0 | AF8: =SUMIFS(PL!AK:AK,PL!$B:$B,$B8) -> 0 | AG8: =SUMIFS(PL!AL:AL,PL!$B:$B,$B8) -> 0 | AH8: =SUMIFS(PL!AM:AM,PL!$B:$B,$B8) -> 0 | AI8: =SUMIFS(PL!AN:AN,PL!$B:$B,$B8) -> 0 | AJ8: =SUMIFS(PL!AS:AS,PL!$B:$B,$B8) -> 0 | AK8: =SUMIFS(PL!AT:AT,PL!$B:$B,$B8) -> 0 | AL8: =SUMIFS(PL!AU:AU,PL!$B:$B,$B8) -> 0 | AM8: =SUMIFS(PL!AV:AV,PL!$B:$B,$B8) -> 0
A9: Lab fees | B9: Lab fees | C9: =SUMIFS($G9:$BC9,$G$5:$BC$5,"<="&EOMONTH(C$5,0),$G$6:$BC$6,"<="&C$5) -> 0 | D9: =SUMIFS($G9:$AT9,$G$5:$AT$5,">"&EOMONTH(D$5,-12),$G$5:$AT$5,"<="&D$5) -> 0 | E9: =SUMIFS($G9:$AT9,$G$5:$AT$5,">"&EOMONTH(E$5,-12),$G$5:$AT$5,"<="&E$5) -> 0 | G9: =SUMIFS(PL!L:L,PL!$B:$B,$B9) -> 0 | H9: =SUMIFS(PL!M:M,PL!$B:$B,$B9) -> 0 | I9: =SUMIFS(PL!N:N,PL!$B:$B,$B9) -> 0 | J9: =SUMIFS(PL!O:O,PL!$B:$B,$B9) -> 0 | K9: =SUMIFS(PL!P:P,PL!$B:$B,$B9) -> 0 | L9: =SUMIFS(PL!Q:Q,PL!$B:$B,$B9) -> 0 | M9: =SUMIFS(PL!R:R,PL!$B:$B,$B9) -> 0 | N9: =SUMIFS(PL!S:S,PL!$B:$B,$B9) -> 0 | O9: =SUMIFS(PL!T:T,PL!$B:$B,$B9) -> 0 | P9: =SUMIFS(PL!U:U,PL!$B:$B,$B9) -> 0 | Q9: =SUMIFS(PL!V:V,PL!$B:$B,$B9) -> 0 | R9: =SUMIFS(PL!W:W,PL!$B:$B,$B9) -> 0 | S9: =SUMIFS(PL!X:X,PL!$B:$B,$B9) -> 0 | T9: =SUMIFS(PL!Y:Y,PL!$B:$B,$B9) -> 0 | U9: =SUMIFS(PL!Z:Z,PL!$B:$B,$B9) -> 0 | V9: =SUMIFS(PL!AA:AA,PL!$B:$B,$B9) -> 0 | W9: =SUMIFS(PL!AB:AB,PL!$B:$B,$B9) -> 0 | X9: =SUMIFS(PL!AC:AC,PL!$B:$B,$B9) -> 0 | Y9: =SUMIFS(PL!AD:AD,PL!$B:$B,$B9) -> 0 | Z9: =SUMIFS(PL!AE:AE,PL!$B:$B,$B9) -> 0 | AA9: =SUMIFS(PL!AF:AF,PL!$B:$B,$B9) -> 0 | AB9: =SUMIFS(PL!AG:AG,PL!$B:$B,$B9) -> 0 | AC9: =SUMIFS(PL!AH:AH,PL!$B:$B,$B9) -> 0 | AD9: =SUMIFS(PL!AI:AI,PL!$B:$B,$B9) -> 0 | AE9: =SUMIFS(PL!AJ:AJ,PL!$B:$B,$B9) -> 0 | AF9: =SUMIFS(PL!AK:AK,PL!$B:$B,$B9) -> 0 | AG9: =SUMIFS(PL!AL:AL,PL!$B:$B,$B9) -> 0 | AH9: =SUMIFS(PL!AM:AM,PL!$B:$B,$B9) -> 0 | AI9: =SUMIFS(PL!AN:AN,PL!$B:$B,$B9) -> 0 | AJ9: =SUMIFS(PL!AS:AS,PL!$B:$B,$B9) -> 0 | AK9: =SUMIFS(PL!AT:AT,PL!$B:$B,$B9) -> 0 | AL9: =SUMIFS(PL!AU:AU,PL!$B:$B,$B9) -> 0 | AM9: =SUMIFS(PL!AV:AV,PL!$B:$B,$B9) -> 0
B10: Cost of goods sold | C10: =SUM(C7:C9) -> 0 | D10: =SUM(D7:D9) -> 0 | E10: =SUM(E7:E9) -> 0 | G10: =SUM(G7:G9) -> 0 | H10: =SUM(H7:H9) -> 0 | I10: =SUM(I7:I9) -> 0 | J10: =SUM(J7:J9) -> 0 | K10: =SUM(K7:K9) -> 0 | L10: =SUM(L7:L9) -> 0 | M10: =SUM(M7:M9) -> 0 | N10: =SUM(N7:N9) -> 0 | ... AM10: =SUM(AM7:AM9) -> 0
B11: Gross profit | C11: =C6-SUM(C7:C9) -> 0 | D11: =D6-SUM(D7:D9) -> 0 | E11: =E6-SUM(E7:E9) -> 0 | G11: =G6-SUM(G7:G9) -> 0 | H11: =H6-SUM(H7:H9) -> 0 | I11: =I6-SUM(I7:I9) -> 0 | J11: =J6-SUM(J7:J9) -> 0 | K11: =K6-SUM(K7:K9) -> 0 | L11: =L6-SUM(L7:L9) -> 0 | M11: =M6-SUM(M7:M9) -> 0 | N11: =N6-SUM(N7:N9) -> 0 | ... AM11: =AM6-SUM(AM7:AM9) -> 0
A13: Doctor wages | B13: Doctor wages | C13: =SUMIFS($G13:$BC13,$G$5:$BC$5,"<="&EOMONTH(C$5,0),$G$6:$BC$6,"<="&C$5) -> 0 | D13: =SUMIFS($G13:$AT13,$G$5:$AT$5,">"&EOMONTH(D$5,-12),$G$5:$AT$5,"<="&D$5) -> 0 | E13: =SUMIFS($G13:$AT13,$G$5:$AT$5,">"&EOMONTH(E$5,-12),$G$5:$AT$5,"<="&E$5) -> 0 | G13: =SUMIFS(PL!L:L,PL!$B:$B,$B13) -> 0 | H13: =SUMIFS(PL!M:M,PL!$B:$B,$B13) -> 0 | I13: =SUMIFS(PL!N:N,PL!$B:$B,$B13) -> 0 | J13: =SUMIFS(PL!O:O,PL!$B:$B,$B13) -> 0 | K13: =SUMIFS(PL!P:P,PL!$B:$B,$B13) -> 0 | L13: =SUMIFS(PL!Q:Q,PL!$B:$B,$B13) -> 0 | M13: =SUMIFS(PL!R:R,PL!$B:$B,$B13) -> 0 | N13: =SUMIFS(PL!S:S,PL!$B:$B,$B13) -> 0 | O13: =SUMIFS(PL!T:T,PL!$B:$B,$B13) -> 0 | P13: =SUMIFS(PL!U:U,PL!$B:$B,$B13) -> 0 | Q13: =SUMIFS(PL!V:V,PL!$B:$B,$B13) -> 0 | R13: =SUMIFS(PL!W:W,PL!$B:$B,$B13) -> 0 | S13: =SUMIFS(PL!X:X,PL!$B:$B,$B13) -> 0 | T13: =SUMIFS(PL!Y:Y,PL!$B:$B,$B13) -> 0 | U13: =SUMIFS(PL!Z:Z,PL!$B:$B,$B13) -> 0 | V13: =SUMIFS(PL!AA:AA,PL!$B:$B,$B13) -> 0 | W13: =SUMIFS(PL!AB:AB,PL!$B:$B,$B13) -> 0 | X13: =SUMIFS(PL!AC:AC,PL!$B:$B,$B13) -> 0 | Y13: =SUMIFS(PL!AD:AD,PL!$B:$B,$B13) -> 0 | Z13: =SUMIFS(PL!AE:AE,PL!$B:$B,$B13) -> 0 | AA13: =SUMIFS(PL!AF:AF,PL!$B:$B,$B13) -> 0 | AB13: =SUMIFS(PL!AG:AG,PL!$B:$B,$B13) -> 0 | AC13: =SUMIFS(PL!AH:AH,PL!$B:$B,$B13) -> 0 | AD13: =SUMIFS(PL!AI:AI,PL!$B:$B,$B13) -> 0 | AE13: =SUMIFS(PL!AJ:AJ,PL!$B:$B,$B13) -> 0 | AF13: =SUMIFS(PL!AK:AK,PL!$B:$B,$B13) -> 0 | AG13: =SUMIFS(PL!AL:AL,PL!$B:$B,$B13) -> 0 | AH13: =SUMIFS(PL!AM:AM,PL!$B:$B,$B13) -> 0 | AI13: =SUMIFS(PL!AN:AN,PL!$B:$B,$B13) -> 0 | AJ13: =SUMIFS(PL!AS:AS,PL!$B:$B,$B13) -> 0 | AK13: =SUMIFS(PL!AT:AT,PL!$B:$B,$B13) -> 0 | AL13: =SUMIFS(PL!AU:AU,PL!$B:$B,$B13) -> 0 | AM13: =SUMIFS(PL!AV:AV,PL!$B:$B,$B13) -> 0
A14: Clinic wages | B14: Clinic wages | C14: =SUMIFS($G14:$BC14,$G$5:$BC$5,"<="&EOMONTH(C$5,0),$G$6:$BC$6,"<="&C$5) -> 0 | D14: =SUMIFS($G14:$AT14,$G$5:$AT$5,">"&EOMONTH(D$5,-12),$G$5:$AT$5,"<="&D$5) -> 0 | E14: =SUMIFS($G14:$AT14,$G$5:$AT$5,">"&EOMONTH(E$5,-12),$G$5:$AT$5,"<="&E$5) -> 0 | G14: =SUMIFS(PL!L:L,PL!$B:$B,$B14) -> 0 | H14: =SUMIFS(PL!M:M,PL!$B:$B,$B14) -> 0 | I14: =SUMIFS(PL!N:N,PL!$B:$B,$B14) -> 0 | J14: =SUMIFS(PL!O:O,PL!$B:$B,$B14) -> 0 | K14: =SUMIFS(PL!P:P,PL!$B:$B,$B14) -> 0 | L14: =SUMIFS(PL!Q:Q,PL!$B:$B,$B14) -> 0 | M14: =SUMIFS(PL!R:R,PL!$B:$B,$B14) -> 0 | N14: =SUMIFS(PL!S:S,PL!$B:$B,$B14) -> 0 | O14: =SUMIFS(PL!T:T,PL!$B:$B,$B14) -> 0 | P14: =SUMIFS(PL!U:U,PL!$B:$B,$B14) -> 0 | Q14: =SUMIFS(PL!V:V,PL!$B:$B,$B14) -> 0 | R14: =SUMIFS(PL!W:W,PL!$B:$B,$B14) -> 0 | S14: =SUMIFS(PL!X:X,PL!$B:$B,$B14) -> 0 | T14: =SUMIFS(PL!Y:Y,PL!$B:$B,$B14) -> 0 | U14: =SUMIFS(PL!Z:Z,PL!$B:$B,$B14) -> 0 | V14: =SUMIFS(PL!AA:AA,PL!$B:$B,$B14) -> 0 | W14: =SUMIFS(PL!AB:AB,PL!$B:$B,$B14) -> 0 | X14: =SUMIFS(PL!AC:AC,PL!$B:$B,$B14) -> 0 | Y14: =SUMIFS(PL!AD:AD,PL!$B:$B,$B14) -> 0 | Z14: =SUMIFS(PL!AE:AE,PL!$B:$B,$B14) -> 0 | AA14: =SUMIFS(PL!AF:AF,PL!$B:$B,$B14) -> 0 | AB14: =SUMIFS(PL!AG:AG,PL!$B:$B,$B14) -> 0 | AC14: =SUMIFS(PL!AH:AH,PL!$B:$B,$B14) -> 0 | AD14: =SUMIFS(PL!AI:AI,PL!$B:$B,$B14) -> 0 | AE14: =SUMIFS(PL!AJ:AJ,PL!$B:$B,$B14) -> 0 | AF14: =SUMIFS(PL!AK:AK,PL!$B:$B,$B14) -> 0 | AG14: =SUMIFS(PL!AL:AL,PL!$B:$B,$B14) -> 0 | AH14: =SUMIFS(PL!AM:AM,PL!$B:$B,$B14) -> 0 | AI14: =SUMIFS(PL!AN:AN,PL!$B:$B,$B14) -> 0 | AJ14: =SUMIFS(PL!AS:AS,PL!$B:$B,$B14) -> 0 | AK14: =SUMIFS(PL!AT:AT,PL!$B:$B,$B14) -> 0 | AL14: =SUMIFS(PL!AU:AU,PL!$B:$B,$B14) -> 0 | AM14: =SUMIFS(PL!AV:AV,PL!$B:$B,$B14) -> 0
A15: Admin wages | B15: Admin wages | C15: =SUMIFS($G15:$BC15,$G$5:$BC$5,"<="&EOMONTH(C$5,0),$G$6:$BC$6,"<="&C$5) -> 0 | D15: =SUMIFS($G15:$AT15,$G$5:$AT$5,">"&EOMONTH(D$5,-12),$G$5:$AT$5,"<="&D$5) -> 0 | E15: =SUMIFS($G15:$AT15,$G$5:$AT$5,">"&EOMONTH(E$5,-12),$G$5:$AT$5,"<="&E$5) -> 0 | G15: =SUMIFS(PL!L:L,PL!$B:$B,$B15) -> 0 | H15: =SUMIFS(PL!M:M,PL!$B:$B,$B15) -> 0 | I15: =SUMIFS(PL!N:N,PL!$B:$B,$B15) -> 0 | J15: =SUMIFS(PL!O:O,PL!$B:$B,$B15) -> 0 | K15: =SUMIFS(PL!P:P,PL!$B:$B,$B15) -> 0 | L15: =SUMIFS(PL!Q:Q,PL!$B:$B,$B15) -> 0 | M15: =SUMIFS(PL!R:R,PL!$B:$B,$B15) -> 0 | N15: =SUMIFS(PL!S:S,PL!$B:$B,$B15) -> 0 | O15: =SUMIFS(PL!T:T,PL!$B:$B,$B15) -> 0 | P15: =SUMIFS(PL!U:U,PL!$B:$B,$B15) -> 0 | Q15: =SUMIFS(PL!V:V,PL!$B:$B,$B15) -> 0 | R15: =SUMIFS(PL!W:W,PL!$B:$B,$B15) -> 0 | S15: =SUMIFS(PL!X:X,PL!$B:$B,$B15) -> 0 | T15: =SUMIFS(PL!Y:Y,PL!$B:$B,$B15) -> 0 | U15: =SUMIFS(PL!Z:Z,PL!$B:$B,$B15) -> 0 | V15: =SUMIFS(PL!AA:AA,PL!$B:$B,$B15) -> 0 | W15: =SUMIFS(PL!AB:AB,PL!$B:$B,$B15) -> 0 | X15: =SUMIFS(PL!AC:AC,PL!$B:$B,$B15) -> 0 | Y15: =SUMIFS(PL!AD:AD,PL!$B:$B,$B15) -> 0 | Z15: =SUMIFS(PL!AE:AE,PL!$B:$B,$B15) -> 0 | AA15: =SUMIFS(PL!AF:AF,PL!$B:$B,$B15) -> 0 | AB15: =SUMIFS(PL!AG:AG,PL!$B:$B,$B15) -> 0 | AC15: =SUMIFS(PL!AH:AH,PL!$B:$B,$B15) -> 0 | AD15: =SUMIFS(PL!AI:AI,PL!$B:$B,$B15) -> 0 | AE15: =SUMIFS(PL!AJ:AJ,PL!$B:$B,$B15) -> 0 | AF15: =SUMIFS(PL!AK:AK,PL!$B:$B,$B15) -> 0 | AG15: =SUMIFS(PL!AL:AL,PL!$B:$B,$B15) -> 0 | AH15: =SUMIFS(PL!AM:AM,PL!$B:$B,$B15) -> 0 | AI15: =SUMIFS(PL!AN:AN,PL!$B:$B,$B15) -> 0 | AJ15: =SUMIFS(PL!AS:AS,PL!$B:$B,$B15) -> 0 | AK15: =SUMIFS(PL!AT:AT,PL!$B:$B,$B15) -> 0 | AL15: =SUMIFS(PL!AU:AU,PL!$B:$B,$B15) -> 0 | AM15: =SUMIFS(PL!AV:AV,PL!$B:$B,$B15) -> 0
B16: Gross wages, total | C16: =SUBTOTAL(9,C13:C15) -> 0 | D16: =SUBTOTAL(9,D13:D15) -> 0 | E16: =SUBTOTAL(9,E13:E15) -> 0 | G16: =SUBTOTAL(9,G13:G15) -> 0 | H16: =SUBTOTAL(9,H13:H15) -> 0 | I16: =SUBTOTAL(9,I13:I15) -> 0 | J16: =SUBTOTAL(9,J13:J15) -> 0 | K16: =SUBTOTAL(9,K13:K15) -> 0 | L16: =SUBTOTAL(9,L13:L15) -> 0 | M16: =SUBTOTAL(9,M13:M15) -> 0 | N16: =SUBTOTAL(9,N13:N15) -> 0 | ... AM16: =SUBTOTAL(9,AM13:AM15) -> 0
A17: Payroll taxes | B17: Payroll taxes | C17: =SUMIFS($G17:$BC17,$G$5:$BC$5,"<="&EOMONTH(C$5,0),$G$6:$BC$6,"<="&C$5) -> 0 | D17: =SUMIFS($G17:$AT17,$G$5:$AT$5,">"&EOMONTH(D$5,-12),$G$5:$AT$5,"<="&D$5) -> 0 | E17: =SUMIFS($G17:$AT17,$G$5:$AT$5,">"&EOMONTH(E$5,-12),$G$5:$AT$5,"<="&E$5) -> 0 | G17: =SUMIFS(PL!L:L,PL!$B:$B,$B17) -> 0 | H17: =SUMIFS(PL!M:M,PL!$B:$B,$B17) -> 0 | I17: =SUMIFS(PL!N:N,PL!$B:$B,$B17) -> 0 | J17: =SUMIFS(PL!O:O,PL!$B:$B,$B17) -> 0 | K17: =SUMIFS(PL!P:P,PL!$B:$B,$B17) -> 0 | L17: =SUMIFS(PL!Q:Q,PL!$B:$B,$B17) -> 0 | M17: =SUMIFS(PL!R:R,PL!$B:$B,$B17) -> 0 | N17: =SUMIFS(PL!S:S,PL!$B:$B,$B17) -> 0 | O17: =SUMIFS(PL!T:T,PL!$B:$B,$B17) -> 0 | P17: =SUMIFS(PL!U:U,PL!$B:$B,$B17) -> 0 | Q17: =SUMIFS(PL!V:V,PL!$B:$B,$B17) -> 0 | R17: =SUMIFS(PL!W:W,PL!$B:$B,$B17) -> 0 | S17: =SUMIFS(PL!X:X,PL!$B:$B,$B17) -> 0 | T17: =SUMIFS(PL!Y:Y,PL!$B:$B,$B17) -> 0 | U17: =SUMIFS(PL!Z:Z,PL!$B:$B,$B17) -> 0 | V17: =SUMIFS(PL!AA:AA,PL!$B:$B,$B17) -> 0 | W17: =SUMIFS(PL!AB:AB,PL!$B:$B,$B17) -> 0 | X17: =SUMIFS(PL!AC:AC,PL!$B:$B,$B17) -> 0 | Y17: =SUMIFS(PL!AD:AD,PL!$B:$B,$B17) -> 0 | Z17: =SUMIFS(PL!AE:AE,PL!$B:$B,$B17) -> 0 | AA17: =SUMIFS(PL!AF:AF,PL!$B:$B,$B17) -> 0 | AB17: =SUMIFS(PL!AG:AG,PL!$B:$B,$B17) -> 0 | AC17: =SUMIFS(PL!AH:AH,PL!$B:$B,$B17) -> 0 | AD17: =SUMIFS(PL!AI:AI,PL!$B:$B,$B17) -> 0 | AE17: =SUMIFS(PL!AJ:AJ,PL!$B:$B,$B17) -> 0 | AF17: =SUMIFS(PL!AK:AK,PL!$B:$B,$B17) -> 0 | AG17: =SUMIFS(PL!AL:AL,PL!$B:$B,$B17) -> 0 | AH17: =SUMIFS(PL!AM:AM,PL!$B:$B,$B17) -> 0 | AI17: =SUMIFS(PL!AN:AN,PL!$B:$B,$B17) -> 0 | AJ17: =SUMIFS(PL!AS:AS,PL!$B:$B,$B17) -> 0 | AK17: =SUMIFS(PL!AT:AT,PL!$B:$B,$B17) -> 0 | AL17: =SUMIFS(PL!AU:AU,PL!$B:$B,$B17) -> 0 | AM17: =SUMIFS(PL!AV:AV,PL!$B:$B,$B17) -> 0
A18: Insurance | B18: Insurance | C18: =SUMIFS($G18:$BC18,$G$5:$BC$5,"<="&EOMONTH(C$5,0),$G$6:$BC$6,"<="&C$5) -> 0 | D18: =SUMIFS($G18:$AT18,$G$5:$AT$5,">"&EOMONTH(D$5,-12),$G$5:$AT$5,"<="&D$5) -> 0 | E18: =SUMIFS($G18:$AT18,$G$5:$AT$5,">"&EOMONTH(E$5,-12),$G$5:$AT$5,"<="&E$5) -> 0 | G18: =SUMIFS(PL!L:L,PL!$B:$B,$B18) -> 0 | H18: =SUMIFS(PL!M:M,PL!$B:$B,$B18) -> 0 | I18: =SUMIFS(PL!N:N,PL!$B:$B,$B18) -> 0 | J18: =SUMIFS(PL!O:O,PL!$B:$B,$B18) -> 0 | K18: =SUMIFS(PL!P:P,PL!$B:$B,$B18) -> 0 | L18: =SUMIFS(PL!Q:Q,PL!$B:$B,$B18) -> 0 | M18: =SUMIFS(PL!R:R,PL!$B:$B,$B18) -> 0 | N18: =SUMIFS(PL!S:S,PL!$B:$B,$B18) -> 0 | O18: =SUMIFS(PL!T:T,PL!$B:$B,$B18) -> 0 | P18: =SUMIFS(PL!U:U,PL!$B:$B,$B18) -> 0 | Q18: =SUMIFS(PL!V:V,PL!$B:$B,$B18) -> 0 | R18: =SUMIFS(PL!W:W,PL!$B:$B,$B18) -> 0 | S18: =SUMIFS(PL!X:X,PL!$B:$B,$B18) -> 0 | T18: =SUMIFS(PL!Y:Y,PL!$B:$B,$B18) -> 0 | U18: =SUMIFS(PL!Z:Z,PL!$B:$B,$B18) -> 0 | V18: =SUMIFS(PL!AA:AA,PL!$B:$B,$B18) -> 0 | W18: =SUMIFS(PL!AB:AB,PL!$B:$B,$B18) -> 0 | X18: =SUMIFS(PL!AC:AC,PL!$B:$B,$B18) -> 0 | Y18: =SUMIFS(PL!AD:AD,PL!$B:$B,$B18) -> 0 | Z18: =SUMIFS(PL!AE:AE,PL!$B:$B,$B18) -> 0 | AA18: =SUMIFS(PL!AF:AF,PL!$B:$B,$B18) -> 0 | AB18: =SUMIFS(PL!AG:AG,PL!$B:$B,$B18) -> 0 | AC18: =SUMIFS(PL!AH:AH,PL!$B:$B,$B18) -> 0 | AD18: =SUMIFS(PL!AI:AI,PL!$B:$B,$B18) -> 0 | AE18: =SUMIFS(PL!AJ:AJ,PL!$B:$B,$B18) -> 0 | AF18: =SUMIFS(PL!AK:AK,PL!$B:$B,$B18) -> 0 | AG18: =SUMIFS(PL!AL:AL,PL!$B:$B,$B18) -> 0 | AH18: =SUMIFS(PL!AM:AM,PL!$B:$B,$B18) -> 0 | AI18: =SUMIFS(PL!AN:AN,PL!$B:$B,$B18) -> 0 | AJ18: =SUMIFS(PL!AS:AS,PL!$B:$B,$B18) -> 0 | AK18: =SUMIFS(PL!AT:AT,PL!$B:$B,$B18) -> 0 | AL18: =SUMIFS(PL!AU:AU,PL!$B:$B,$B18) -> 0 | AM18: =SUMIFS(PL!AV:AV,PL!$B:$B,$B18) -> 0
A19: Employee 401(k) | B19: Employee 401(k) | C19: =SUMIFS($G19:$BC19,$G$5:$BC$5,"<="&EOMONTH(C$5,0),$G$6:$BC$6,"<="&C$5) -> 0 | D19: =SUMIFS($G19:$AT19,$G$5:$AT$5,">"&EOMONTH(D$5,-12),$G$5:$AT$5,"<="&D$5) -> 0 | E19: =SUMIFS($G19:$AT19,$G$5:$AT$5,">"&EOMONTH(E$5,-12),$G$5:$AT$5,"<="&E$5) -> 0 | G19: =SUMIFS(PL!L:L,PL!$B:$B,$B19) -> 0 | H19: =SUMIFS(PL!M:M,PL!$B:$B,$B19) -> 0 | I19: =SUMIFS(PL!N:N,PL!$B:$B,$B19) -> 0 | J19: =SUMIFS(PL!O:O,PL!$B:$B,$B19) -> 0 | K19: =SUMIFS(PL!P:P,PL!$B:$B,$B19) -> 0 | L19: =SUMIFS(PL!Q:Q,PL!$B:$B,$B19) -> 0 | M19: =SUMIFS(PL!R:R,PL!$B:$B,$B19) -> 0 | N19: =SUMIFS(PL!S:S,PL!$B:$B,$B19) -> 0 | O19: =SUMIFS(PL!T:T,PL!$B:$B,$B19) -> 0 | P19: =SUMIFS(PL!U:U,PL!$B:$B,$B19) -> 0 | Q19: =SUMIFS(PL!V:V,PL!$B:$B,$B19) -> 0 | R19: =SUMIFS(PL!W:W,PL!$B:$B,$B19) -> 0 | S19: =SUMIFS(PL!X:X,PL!$B:$B,$B19) -> 0 | T19: =SUMIFS(PL!Y:Y,PL!$B:$B,$B19) -> 0 | U19: =SUMIFS(PL!Z:Z,PL!$B:$B,$B19) -> 0 | V19: =SUMIFS(PL!AA:AA,PL!$B:$B,$B19) -> 0 | W19: =SUMIFS(PL!AB:AB,PL!$B:$B,$B19) -> 0 | X19: =SUMIFS(PL!AC:AC,PL!$B:$B,$B19) -> 0 | Y19: =SUMIFS(PL!AD:AD,PL!$B:$B,$B19) -> 0 | Z19: =SUMIFS(PL!AE:AE,PL!$B:$B,$B19) -> 0 | AA19: =SUMIFS(PL!AF:AF,PL!$B:$B,$B19) -> 0 | AB19: =SUMIFS(PL!AG:AG,PL!$B:$B,$B19) -> 0 | AC19: =SUMIFS(PL!AH:AH,PL!$B:$B,$B19) -> 0 | AD19: =SUMIFS(PL!AI:AI,PL!$B:$B,$B19) -> 0 | AE19: =SUMIFS(PL!AJ:AJ,PL!$B:$B,$B19) -> 0 | AF19: =SUMIFS(PL!AK:AK,PL!$B:$B,$B19) -> 0 | AG19: =SUMIFS(PL!AL:AL,PL!$B:$B,$B19) -> 0 | AH19: =SUMIFS(PL!AM:AM,PL!$B:$B,$B19) -> 0 | AI19: =SUMIFS(PL!AN:AN,PL!$B:$B,$B19) -> 0 | AJ19: =SUMIFS(PL!AS:AS,PL!$B:$B,$B19) -> 0 | AK19: =SUMIFS(PL!AT:AT,PL!$B:$B,$B19) -> 0 | AL19: =SUMIFS(PL!AU:AU,PL!$B:$B,$B19) -> 0 | AM19: =SUMIFS(PL!AV:AV,PL!$B:$B,$B19) -> 0
B20: Salary, payroll taxes, and benefits, total | C20: =SUM(C16:C19) -> 0 | D20: =SUM(D16:D19) -> 0 | E20: =SUM(E16:E19) -> 0 | G20: =SUM(G16:G19) -> 0 | H20: =SUM(H16:H19) -> 0 | I20: =SUM(I16:I19) -> 0 | J20: =SUM(J16:J19) -> 0 | K20: =SUM(K16:K19) -> 0 | L20: =SUM(L16:L19) -> 0 | M20: =SUM(M16:M19) -> 0 | N20: =SUM(N16:N19) -> 0 | ... AM20: =SUM(AM16:AM19) -> 0
B21: Rent - real property | C21: =SUMIFS($G21:$BC21,$G$5:$BC$5,"<="&EOMONTH(C$5,0),$G$6:$BC$6,"<="&C$5) -> 0 | D21: =SUMIFS($G21:$AT21,$G$5:$AT$5,">"&EOMONTH(D$5,-12),$G$5:$AT$5,"<="&D$5) -> 0 | E21: =SUMIFS($G21:$AT21,$G$5:$AT$5,">"&EOMONTH(E$5,-12),$G$5:$AT$5,"<="&E$5) -> 0 | G21: =SUMIFS(PL!L:L,PL!$B:$B,$B21) -> 0 | H21: =SUMIFS(PL!M:M,PL!$B:$B,$B21) -> 0 | I21: =SUMIFS(PL!N:N,PL!$B:$B,$B21) -> 0 | J21: =SUMIFS(PL!O:O,PL!$B:$B,$B21) -> 0 | K21: =SUMIFS(PL!P:P,PL!$B:$B,$B21) -> 0 | L21: =SUMIFS(PL!Q:Q,PL!$B:$B,$B21) -> 0 | M21: =SUMIFS(PL!R:R,PL!$B:$B,$B21) -> 0 | N21: =SUMIFS(PL!S:S,PL!$B:$B,$B21) -> 0 | O21: =SUMIFS(PL!T:T,PL!$B:$B,$B21) -> 0 | P21: =SUMIFS(PL!U:U,PL!$B:$B,$B21) -> 0 | Q21: =SUMIFS(PL!V:V,PL!$B:$B,$B21) -> 0 | R21: =SUMIFS(PL!W:W,PL!$B:$B,$B21) -> 0 | S21: =SUMIFS(PL!X:X,PL!$B:$B,$B21) -> 0 | T21: =SUMIFS(PL!Y:Y,PL!$B:$B,$B21) -> 0 | U21: =SUMIFS(PL!Z:Z,PL!$B:$B,$B21) -> 0 | V21: =SUMIFS(PL!AA:AA,PL!$B:$B,$B21) -> 0 | W21: =SUMIFS(PL!AB:AB,PL!$B:$B,$B21) -> 0 | X21: =SUMIFS(PL!AC:AC,PL!$B:$B,$B21) -> 0 | Y21: =SUMIFS(PL!AD:AD,PL!$B:$B,$B21) -> 0 | Z21: =SUMIFS(PL!AE:AE,PL!$B:$B,$B21) -> 0 | AA21: =SUMIFS(PL!AF:AF,PL!$B:$B,$B21) -> 0 | AB21: =SUMIFS(PL!AG:AG,PL!$B:$B,$B21) -> 0 | AC21: =SUMIFS(PL!AH:AH,PL!$B:$B,$B21) -> 0 | AD21: =SUMIFS(PL!AI:AI,PL!$B:$B,$B21) -> 0 | AE21: =SUMIFS(PL!AJ:AJ,PL!$B:$B,$B21) -> 0 | AF21: =SUMIFS(PL!AK:AK,PL!$B:$B,$B21) -> 0 | AG21: =SUMIFS(PL!AL:AL,PL!$B:$B,$B21) -> 0 | AH21: =SUMIFS(PL!AM:AM,PL!$B:$B,$B21) -> 0 | AI21: =SUMIFS(PL!AN:AN,PL!$B:$B,$B21) -> 0 | AJ21: =SUMIFS(PL!AS:AS,PL!$B:$B,$B21) -> 0 | AK21: =SUMIFS(PL!AT:AT,PL!$B:$B,$B21) -> 0 | AL21: =SUMIFS(PL!AU:AU,PL!$B:$B,$B21) -> 0 | AM21: =SUMIFS(PL!AV:AV,PL!$B:$B,$B21) -> 0
B22: Property tax expense | C22: =SUMIFS($G22:$BC22,$G$5:$BC$5,"<="&EOMONTH(C$5,0),$G$6:$BC$6,"<="&C$5) -> 0 | D22: =SUMIFS($G22:$AT22,$G$5:$AT$5,">"&EOMONTH(D$5,-12),$G$5:$AT$5,"<="&D$5) -> 0 | E22: =SUMIFS($G22:$AT22,$G$5:$AT$5,">"&EOMONTH(E$5,-12),$G$5:$AT$5,"<="&E$5) -> 0 | G22: =SUMIFS(PL!L:L,PL!$B:$B,$B22) -> 0 | H22: =SUMIFS(PL!M:M,PL!$B:$B,$B22) -> 0 | I22: =SUMIFS(PL!N:N,PL!$B:$B,$B22) -> 0 | J22: =SUMIFS(PL!O:O,PL!$B:$B,$B22) -> 0 | K22: =SUMIFS(PL!P:P,PL!$B:$B,$B22) -> 0 | L22: =SUMIFS(PL!Q:Q,PL!$B:$B,$B22) -> 0 | M22: =SUMIFS(PL!R:R,PL!$B:$B,$B22) -> 0 | N22: =SUMIFS(PL!S:S,PL!$B:$B,$B22) -> 0 | O22: =SUMIFS(PL!T:T,PL!$B:$B,$B22) -> 0 | P22: =SUMIFS(PL!U:U,PL!$B:$B,$B22) -> 0 | Q22: =SUMIFS(PL!V:V,PL!$B:$B,$B22) -> 0 | R22: =SUMIFS(PL!W:W,PL!$B:$B,$B22) -> 0 | S22: =SUMIFS(PL!X:X,PL!$B:$B,$B22) -> 0 | T22: =SUMIFS(PL!Y:Y,PL!$B:$B,$B22) -> 0 | U22: =SUMIFS(PL!Z:Z,PL!$B:$B,$B22) -> 0 | V22: =SUMIFS(PL!AA:AA,PL!$B:$B,$B22) -> 0 | W22: =SUMIFS(PL!AB:AB,PL!$B:$B,$B22) -> 0 | X22: =SUMIFS(PL!AC:AC,PL!$B:$B,$B22) -> 0 | Y22: =SUMIFS(PL!AD:AD,PL!$B:$B,$B22) -> 0 | Z22: =SUMIFS(PL!AE:AE,PL!$B:$B,$B22) -> 0 | AA22: =SUMIFS(PL!AF:AF,PL!$B:$B,$B22) -> 0 | AB22: =SUMIFS(PL!AG:AG,PL!$B:$B,$B22) -> 0 | AC22: =SUMIFS(PL!AH:AH,PL!$B:$B,$B22) -> 0 | AD22: =SUMIFS(PL!AI:AI,PL!$B:$B,$B22) -> 0 | AE22: =SUMIFS(PL!AJ:AJ,PL!$B:$B,$B22) -> 0 | AF22: =SUMIFS(PL!AK:AK,PL!$B:$B,$B22) -> 0 | AG22: =SUMIFS(PL!AL:AL,PL!$B:$B,$B22) -> 0 | AH22: =SUMIFS(PL!AM:AM,PL!$B:$B,$B22) -> 0 | AI22: =SUMIFS(PL!AN:AN,PL!$B:$B,$B22) -> 0 | AJ22: =SUMIFS(PL!AS:AS,PL!$B:$B,$B22) -> 0 | AK22: =SUMIFS(PL!AT:AT,PL!$B:$B,$B22) -> 0 | AL22: =SUMIFS(PL!AU:AU,PL!$B:$B,$B22) -> 0 | AM22: =SUMIFS(PL!AV:AV,PL!$B:$B,$B22) -> 0
